Workbook

Sheet 8.6配料测试汇总
A1: 序号 | B1: 配方ID | C1: 线棒号 | D1: IR190(9型环氧树脂36%固含） | E1: RF401(PR401) | F1: RF160(PR33160G) | G1: IR809 55%(PR309 稀释55%) | H1: RF516（PR516） | I1: RF950（PR8219-50） | J1: RF956（PR8219-65） | K1: RH601（SM601RX75) | L1: 住友55754G | M1: 1510蜡25%工作液 | N1: AZ088（BYK088) | O1: 外加正丁醇 | P1: 补加混合液（乙二醇单丁醚：二甲苯=2:1） | Q1: 10%磷酸 | R1: T弯(mm) | S1: MEK擦拭(次) | T1: 水煮（等级）
A2: 1 | B2: D1-1 | C2: 14# | D2: 66 | E2: 0 | F2: 0 | G2: 0.12 | H2: 2.64 | I2: 0 | J2: 1.53 | K2: 0 | L2: 0 | M2: 0.79 | N2: 0.06 | O2: 1.48 | P2: 1.27 | Q2: 0 | R2: =IFERROR(VLOOKUP($B2&"|"&$C2,测试原始数据!$A$2:$G$131,4,FALSE),"——") -> 17.415 | S2: =IFERROR(VLOOKUP($B2&"|"&$C2,测试原始数据!$A$2:$G$131,5,FALSE),"——") -> 9 | T2: =IFERROR(VLOOKUP($B2&"|"&$C2,[1]测试原始数据!$A$2:$G$131,6,FALSE),"——") -> 4
A3: 2 | B3: D1-2 | C3: 14# | D3: 66.09 | E3: 0.96 | F3: 0 | G3: 0 | H3: 0.48 | I3: 6.29 | J3: 6.65 | K3: 0 | L3: 0.42 | M3: 2.98 | N3: 0.06 | O3: 5.49 | P3: 1.55 | Q3: 2.4 | R3: =IFERROR(VLOOKUP($B3&"|"&$C3,测试原始数据!$A$2:$G$131,4,FALSE),"——") -> 19.22 | S3: =IFERROR(VLOOKUP($B3&"|"&$C3,测试原始数据!$A$2:$G$131,5,FALSE),"——") -> 161 | T3: =IFERROR(VLOOKUP($B3&"|"&$C3,[1]测试原始数据!$A$2:$G$131,6,FALSE),"——") -> 2
A4: 3 | B4: D1-3 | C4: 14# | D4: 66.08 | E4: 0 | F4: 0 | G4: 0.42 | H4: 2.64 | I4: 4.89 | J4: 0 | K4: 0.46 | L4: 0 | M4: 2.13 | N4: 0.06 | O4: 0.08 | P4: 3.17 | Q4: 0 | R4: =IFERROR(VLOOKUP($B4&"|"&$C4,测试原始数据!$A$2:$G$131,4,FALSE),"——") -> 15.69 | S4: =IFERROR(VLOOKUP($B4&"|"&$C4,测试原始数据!$A$2:$G$131,5,FALSE),"——") -> 10 | T4: =IFERROR(VLOOKUP($B4&"|"&$C4,[1]测试原始数据!$A$2:$G$131,6,FALSE),"——") -> 4
A5: 4 | B5: D1-4 | C5: 14# | D5: 66.08 | E5: 0.34 | F5: 11.73 | G5: 0 | H5: 0 | I5: 0.46 | J5: 0 | K5: 0 | L5: 0 | M5: 3 | N5: 0.06 | O5: 4.11 | P5: 6.24 | Q5: 1.79 | R5: =IFERROR(VLOOKUP($B5&"|"&$C5,测试原始数据!$A$2:$G$131,4,FALSE),"——") -> 18.05 | S5: =IFERROR(VLOOKUP($B5&"|"&$C5,测试原始数据!$A$2:$G$131,5,FALSE),"——") -> 98 | T5: =IFERROR(VLOOKUP($B5&"|"&$C5,[1]测试原始数据!$A$2:$G$131,6,FALSE),"——") -> 3
A6: 5 | B6: D1-5 | C6: 14# | D6: 66.24 | E6: 0 | F6: 1.02 | G6: 0.51 | H6: 6.18 | I6: 3.17 | J6: 6.81 | K6: 3.16 | L6: 1.18 | M6: 3.6 | N6: 0.06 | O6: 7.69 | P6: 6.52 | Q6: 2.57 | R6: =IFERROR(VLOOKUP($B6&"|"&$C6,测试原始数据!$A$2:$G$131,4,FALSE),"——") -> 20.8 | S6: =IFERROR(VLOOKUP($B6&"|"&$C6,测试原始数据!$A$2:$G$131,5,FALSE),"——") -> 300+ | T6: =IFERROR(VLOOKUP($B6&"|"&$C6,[1]测试原始数据!$A$2:$G$131,6,FALSE),"——") -> 3
A7: 6 | B7: D1-6 | C7: 14# | D7: 66.05 | E7: 0 | F7: 1.18 | G7: 0.5 | H7: 0 | I7: 0.23 | J7: 3.98 | K7: 2.25 | L7: 0 | M7: 0.78 | N7: 0.06 | O7: 0.38 | P7: 5.86 | Q7: 0.32 | R7: =IFERROR(VLOOKUP($B7&"|"&$C7,测试原始数据!$A$2:$G$131,4,FALSE),"——") -> 14.365 | S7: =IFERROR(VLOOKUP($B7&"|"&$C7,测试原始数据!$A$2:$G$131,5,FALSE),"——") -> 5 | T7: =IFERROR(VLOOKUP($B7&"|"&$C7,[1]测试原始数据!$A$2:$G$131,6,FALSE),"——") -> 4
A8: 7 | B8: D1-7 | C8: 14# | D8: 66.21 | E8: 2.49 | F8: 0 | G8: 0 | H8: 0 | I8: 0 | J8: 0 | K8: 0.41 | L8: 0.9 | M8: 2.05 | N8: 0.06 | O8: 0.54 | P8: 2.52 | Q8: 0 | R8: =IFERROR(VLOOKUP($B8&"|"&$C8,测试原始数据!$A$2:$G$131,4,FALSE),"——") -> 16.535 | S8: =IFERROR(VLOOKUP($B8&"|"&$C8,测试原始数据!$A$2:$G$131,5,FALSE),"——") -> 32 | T8: =IFERROR(VLOOKUP($B8&"|"&$C8,[1]测试原始数据!$A$2:$G$131,6,FALSE),"——") -> 4
A9: 8 | B9: D1-8 | C9: 14# | D9: 66.23 | E9: 0 | F9: 1.15 | G9: 0.19 | H9: 0 | I9: 0.86 | J9: 6.55 | K9: 0 | L9: 0 | M9: 0.69 | N9: 0.06 | O9: 5.72 | P9: 0.88 | Q9: 0 | R9: =IFERROR(VLOOKUP($B9&"|"&$C9,测试原始数据!$A$2:$G$131,4,FALSE),"——") -> 15.225 | S9: =IFERROR(VLOOKUP($B9&"|"&$C9,测试原始数据!$A$2:$G$131,5,FALSE),"——") -> 4 | T9: =IFERROR(VLOOKUP($B9&"|"&$C9,[1]测试原始数据!$A$2:$G$131,6,FALSE),"——") -> 4
A10: 9 | B10: D1-9 | C10: 14# | D10: 65.99 | E10: 2.63 | F10: 0 | G10: 0 | H10: 6.44 | I10: 5.96 | J10: 0 | K10: 0 | L10: 0.12 | M10: 2.59 | N10: 0.06 | O10: 4.77 | P10: 2.77 | Q10: 1.54 | R10: =IFERROR(VLOOKUP($B10&"|"&$C10,测试原始数据!$A$2:$G$131,4,FALSE),"——") -> 22.32 | S10: =IFERROR(VLOOKUP($B10&"|"&$C10,测试原始数据!$A$2:$G$131,5,FALSE),"——") -> 172 | T10: =IFERROR(VLOOKUP($B10&"|"&$C10,[1]测试原始数据!$A$2:$G$131,6,FALSE),"——") -> 2
A11: 10 | B11: D1-10 | C11: 14# | D11: 66.08 | E11: 2.28 | F11: 0 | G11: 0.2 | H11: 0 | I11: 0 | J11: 5.89 | K11: 1.77 | L11: 0 | M11: 2.79 | N11: 0.06 | O11: 6.1 | P11: 0.05 | Q11: 2.44 | R11: =IFERROR(VLOOKUP($B11&"|"&$C11,测试原始数据!$A$2:$G$131,4,FALSE),"——") -> 16.09 | S11: =IFERROR(VLOOKUP($B11&"|"&$C11,测试原始数据!$A$2:$G$131,5,FALSE),"——") -> 95 | T11: =IFERROR(VLOOKUP($B11&"|"&$C11,[1]测试原始数据!$A$2:$G$131,6,FALSE),"——") -> 4
A12: 11 | B12: D1-11 | C12: 14# | D12: 65.99 | E12: 0 | F12: 2.91 | G12: 0.58 | H12: 5.61 | I12: 4.87 | J12: 3.45 | K12: 0 | L12: 0 | M12: 1 | N12: 0.06 | O12: 9.04 | P12: 1.84 | Q12: 0 | R12: =IFERROR(VLOOKUP($B12&"|"&$C12,测试原始数据!$A$2:$G$131,4,FALSE),"——") -> 17.145 | S12: =IFERROR(VLOOKUP($B12&"|"&$C12,测试原始数据!$A$2:$G$131,5,FALSE),"——") -> 33 | T12: =IFERROR(VLOOKUP($B12&"|"&$C12,[1]测试原始数据!$A$2:$G$131,6,FALSE),"——") -> 2
A13: 12 | B13: D1-12 | C13: 14# | D13: 66.16 | E13: 0 | F13: 0.38 | G13: 0 | H13: 0.47 | I13: 6.58 | J13: 2.35 | K13: 0 | L13: 0 | M13: 0.96 | N13: 0.06 | O13: 3.85 | P13: 0.98 | Q13: 0 | R13: =IFERROR(VLOOKUP($B13&"|"&$C13,测试原始数据!$A$2:$G$131,4,FALSE),"——") -> 14.46 | S13: =IFERROR(VLOOKUP($B13&"|"&$C13,测试原始数据!$A$2:$G$131,5,FALSE),"——") -> 11 | T13: =IFERROR(VLOOKUP($B13&"|"&$C13,[1]测试原始数据!$A$2:$G$131,6,FALSE),"——") -> 4
... A27: 26 | B27: D1-24 | C27: 18# | D27: 65.83 | E27: 1.37 | F27: 5.95 | G27: 0.45 | H27: 2.38 | I27: 2.7 | J27: 2.84 | K27: 2.15 | L27: 0.73 | M27: 1.91 | N27: 0.06 | O27: 4.88 | P27: 8.51 | Q27: 1.47 | R27: =IFERROR(VLOOKUP($B27&"|"&$C27,测试原始数据!$A$2:$G$131,4,FALSE),"——") -> 16.72 | S27: =IFERROR(VLOOKUP($B27&"|"&$C27,测试原始数据!$A$2:$G$131,5,FALSE),"——") -> 125 | T27: =IFERROR(VLOOKUP($B27&"|"&$C27,[1]测试原始数据!$A$2:$G$131,6,FALSE),"——") -> 4
A28: 27 | B28: D2-1 | C28: 14# | D28: 66.01 | E28: 1.34 | F28: 5.93 | G28: 0.4 | H28: 2.19 | I28: 3.35 | J28: 2.92 | K28: 2.14 | L28: 0.77 | M28: 1.83 | N28: 0.06 | O28: 4.71 | P28: 9.03 | Q28: 1.56 | R28: =IFERROR(VLOOKUP($B28&"|"&$C28,测试原始数据!$A$2:$G$131,4,FALSE),"——") -> 19.32 | S28: =IFERROR(VLOOKUP($B28&"|"&$C28,测试原始数据!$A$2:$G$131,5,FALSE),"——") -> 68 | T28: 4
A29: 28 | B29: D2-2 | C29: 14# | D29: 66.03 | E29: 0.71 | F29: 0 | G29: 0 | H29: 6.49 | I29: 3.79 | J29: 7.06 | K29: 1.22 | L29: 0 | M29: 3.35 | N29: 0.06 | O29: 6.9 | P29: 4.54 | Q29: 1.94 | R29: =IFERROR(VLOOKUP($B29&"|"&$C29,测试原始数据!$A$2:$G$131,4,FALSE),"——") -> 18.95 | S29: =IFERROR(VLOOKUP($B29&"|"&$C29,测试原始数据!$A$2:$G$131,5,FALSE),"——") -> 76 | T29: 2
A30: 29 | B30: D2-3 | C30: 14# | D30: 65.85 | E30: 0 | F30: 11.02 | G30: 0.43 | H30: 0 | I30: 1.6 | J30: 2.04 | K30: 0 | L30: 0 | M30: 3.03 | N30: 0.06 | O30: 0.92 | P30: 9.77 | Q30: 2.52 | R30: =IFERROR(VLOOKUP($B30&"|"&$C30,测试原始数据!$A$2:$G$131,4,FALSE),"——") -> 20.57 | S30: =IFERROR(VLOOKUP($B30&"|"&$C30,测试原始数据!$A$2:$G$131,5,FALSE),"——") -> 60 | T30: 4+
A31: 30 | B31: D2-4 | C31: 14# | D31: 66.08 | E31: 0.11 | F31: 0 | G31: 0 | H31: 0.47 | I31: 6.79 | J31: 0 | K31: 0 | L31: 0 | M31: 1.13 | N31: 0.06 | O31: 2.36 | P31: 0.22 | Q31: 0 | R31: =IFERROR(VLOOKUP($B31&"|"&$C31,测试原始数据!$A$2:$G$131,4,FALSE),"——") -> 14.695 | S31: =IFERROR(VLOOKUP($B31&"|"&$C31,测试原始数据!$A$2:$G$131,5,FALSE),"——") -> 9 | T31: 4+
A32: 31 | B32: D2-5 | C32: 14# | D32: 66.13 | E32: 2.6 | F32: 0 | G32: 0 | H32: 0 | I32: 1.01 | J32: 6.94 | K32: 0 | L32: 0.11 | M32: 2.67 | N32: 0.06 | O32: 7.12 | P32: 0.39 | Q32: 0.71 | R32: =IFERROR(VLOOKUP($B32&"|"&$C32,测试原始数据!$A$2:$G$131,4,FALSE),"——") -> 14.215 | S32: =IFERROR(VLOOKUP($B32&"|"&$C32,测试原始数据!$A$2:$G$131,5,FALSE),"——") -> 40 | T32: 3
A33: 32 | B33: D2-6 | C33: 14# | D33: 65.98 | E33: 0.62 | F33: 7.96 | G33: 0.52 | H33: 6.63 | I33: 0 | J33: 0 | K33: 0.59 | L33: 0 | M33: 3.17 | N33: 0.06 | O33: 9.91 | P33: 1.59 | Q33: 1.51 | R33: =IFERROR(VLOOKUP($B33&"|"&$C33,测试原始数据!$A$2:$G$131,4,FALSE),"——") -> 20.335 | S33: =IFERROR(VLOOKUP($B33&"|"&$C33,测试原始数据!$A$2:$G$131,5,FALSE),"——") -> 112 | T33: 4+
A34: 33 | B34: D2-7 | C34: 14# | D34: 66.01 | E34: 2.3 | F34: 0 | G34: 0.53 | H34: 0 | I34: 0 | J34: 0 | K34: 2.07 | L34: 0 | M34: 0.63 | N34: 0.06 | O34: 2.76 | P34: 1 | Q34: 1.92 | R34: =IFERROR(VLOOKUP($B34&"|"&$C34,测试原始数据!$A$2:$G$131,4,FALSE),"——") -> 12.485 | S34: =IFERROR(VLOOKUP($B34&"|"&$C34,测试原始数据!$A$2:$G$131,5,FALSE),"——") -> 79 | T34: 2
A35: 34 | B35: D2-8 | C35: 14# | D35: 65.86 | E35: 0.63 | F35: 5.66 | G35: 0.19 | H35: 4.87 | I35: 6.77 | J35: 0 | K35: 0.68 | L35: 0 | M35: 3.16 | N35: 0.06 | O35: 9.44 | P35: 0.85 | Q35: 2.1 | R35: =IFERROR(VLOOKUP($B35&"|"&$C35,测试原始数据!$A$2:$G$131,4,FALSE),"——") -> 20.9 | S35: =IFERROR(VLOOKUP($B35&"|"&$C35,测试原始数据!$A$2:$G$131,5,FALSE),"——") -> 131 | T35: 4+
A36: 35 | B36: D2-9 | C36: 14# | D36: 65.94 | E36: 0 | F36: 0 | G36: 0.4 | H36: 4.18 | I36: 0 | J36: 6.24 | K36: 0 | L36: 0 | M36: 0.69 | N36: 0.06 | O36: 3.73 | P36: 3.72 | Q36: 0 | R36: =IFERROR(VLOOKUP($B36&"|"&$C36,测试原始数据!$A$2:$G$131,4,FALSE),"——") -> 15.53 | S36: =IFERROR(VLOOKUP($B36&"|"&$C36,测试原始数据!$A$2:$G$131,5,FALSE),"——") -> 5 | T36: 4+
A37: 36 | B37: D2-10 | C37: 14# | D37: 65.97 | E37: 0.44 | F37: 11.76 | G37: 0.29 | H37: 0 | I37: 0 | J37: 0 | K37: 0 | L37: 0 | M37: 0.92 | N37: 0.06 | O37: 10.49 | P37: 1.51 | Q37: 0.17 | R37: =IFERROR(VLOOKUP($B37&"|"&$C37,测试原始数据!$A$2:$G$131,4,FALSE),"——") -> 14.995 | S37: =IFERROR(VLOOKUP($B37&"|"&$C37,测试原始数据!$A$2:$G$131,5,FALSE),"——") -> 60 | T37: 2
A38: 37 | B38: D2-11 | C38: 14# | D38: 66.04 | E38: 0 | F38: 1.38 | G38: 0 | H38: 0.79 | I38: 6.21 | J38: 6.68 | K38: 0 | L38: 0.28 | M38: 2.91 | N38: 0.06 | O38: 7.66 | P38: 0.21 | Q38: 1.34 | R38: =IFERROR(VLOOKUP($B38&"|"&$C38,测试原始数据!$A$2:$G$131,4,FALSE),"——") -> 17.04 | S38: =IFERROR(VLOOKUP($B38&"|"&$C38,测试原始数据!$A$2:$G$131,5,FALSE),"——") -> 65 | T38: 2
A39: 38 | B39: D2-12 | C39: 14# | D39: 66.04 | E39: 2.7 | F39: 0 | G39: 0 | H39: 0.28 | I39: 6.56 | J39: 6.4 | K39: 2.8 | L39: 1.22 | M39: 0.8 | N39: 0.06 | O39: 3.13 | P39: 11.39 | Q39: 0.24 | R39: =IFERROR(VLOOKUP($B39&"|"&$C39,测试原始数据!$A$2:$G$131,4,FALSE),"——") -> 17.89 | S39: =IFERROR(VLOOKUP($B39&"|"&$C39,测试原始数据!$A$2:$G$131,5,FALSE),"——") -> 50 | T39: 2
A40: 39 | B40: D2-13 | C40: 14# | D40: 65.99 | E40: 0.32 | F40: 7.54 | G40: 0 | H40: 0.13 | I40: 6.41 | J40: 4.52 | K40: 3.77 | L40: 0 | M40: 3.4 | N40: 0.06 | O40: 6.46 | P40: 9.19 | Q40: 0.93 | R40: =IFERROR(VLOOKUP($B40&"|"&$C40,测试原始数据!$A$2:$G$131,4,FALSE),"——") -> 16.31 | S40: =IFERROR(VLOOKUP($B40&"|"&$C40,测试原始数据!$A$2:$G$131,5,FALSE),"——") -> 45 | T40: 2
A41: 40 | B41: D2-14 | C41: 14# | D41: 66.13 | E41: 0.94 | F41: 11.43 | G41: 0.33 | H41: 0 | I41: 0 | J41: 0 | K41: 2.95 | L41: 0 | M41: 3.22 | N41: 0.06 | O41: 12.21 | P41: 0.5 | Q41: 2.11 | R41: =IFERROR(VLOOKUP($B41&"|"&$C41,测试原始数据!$A$2:$G$131,4,FALSE),"——") -> 16.98 | S41: =IFERROR(VLOOKUP($B41&"|"&$C41,测试原始数据!$A$2:$G$131,5,FALSE),"——") -> 80 | T41: 4+
A42: 41 | B42: D2-15 | C42: 14# | D42: 65.96 | E42: 1.19 | F42: 8.77 | G42: 0.41 | H42: 6.03 | I42: 0 | J42: 0 | K42: 2.8 | L42: 0 | M42: 3.44 | N42: 0.06 | O42: 0.25 | P42: 14.2 | Q42: 1.79 | R42: =IFERROR(VLOOKUP($B42&"|"&$C42,测试原始数据!$A$2:$G$131,4,FALSE),"——") -> 19.41 | S42: =IFERROR(VLOOKUP($B42&"|"&$C42,测试原始数据!$A$2:$G$131,5,FALSE),"——") -> 76 | T42: 4
A43: 42 | B43: D2-16 | C43: 14# | D43: 66.05 | E43: 2.24 | F43: 7.42 | G43: 0.51 | H43: 0 | I43: 0 | J43: 4.74 | K43: 2.41 | L43: 0 | M43: 2.42 | N43: 0.06 | O43: 2.56 | P43: 10.85 | Q43: 2.35 | R43: =IFERROR(VLOOKUP($B43&"|"&$C43,测试原始数据!$A$2:$G$131,4,FALSE),"——") -> 18.62 | S43: =IFERROR(VLOOKUP($B43&"|"&$C43,测试原始数据!$A$2:$G$131,5,FALSE),"——") -> 60 | T43: 4+
A44: 43 | B44: D2-17 | C44: 14# | D44: 66 | E44: 0 | F44: 0.25 | G44: 0.16 | H44: 6.66 | I44: 3.14 | J44: 6.49 | K44: 2.13 | L44: 0.63 | M44: 3.28 | N44: 0.06 | O44: 3.85 | P44: 7.3 | Q44: 2.24 | R44: =IFERROR(VLOOKUP($B44&"|"&$C44,测试原始数据!$A$2:$G$131,4,FALSE),"——") -> 18.81 | S44: =IFERROR(VLOOKUP($B44&"|"&$C44,测试原始数据!$A$2:$G$131,5,FALSE),"——") -> 120 | T44: 4+
A45: 44 | B45: D2-18 | C45: 14# | D45: 65.98 | E45: 0.36 | F45: 11.82 | G45: 0.44 | H45: 0 | I45: 0 | J45: 0 | K45: 0.82 | L45: 0 | M45: 2.95 | N45: 0.06 | O45: 1.99 | P45: 9.74 | Q45: 0.61 | R45: =IFERROR(VLOOKUP($B45&"|"&$C45,测试原始数据!$A$2:$G$131,4,FALSE),"——") -> 15.825 | S45: =IFERROR(VLOOKUP($B45&"|"&$C45,测试原始数据!$A$2:$G$131,5,FALSE),"——") -> 45 | T45: 4
A46: 45 | B46: D2-19 | C46: 14# | D46: 66.05 | E46: 0 | F46: 4.62 | G46: 0.4 | H46: 0 | I46: 5.73 | J46: 6.51 | K46: 0 | L46: 0 | M46: 3.15 | N46: 0.06 | O46: 7.99 | P46: 1.43 | Q46: 2.16 | R46: =IFERROR(VLOOKUP($B46&"|"&$C46,测试原始数据!$A$2:$G$131,4,FALSE),"——") -> 19.77 | S46: =IFERROR(VLOOKUP($B46&"|"&$C46,测试原始数据!$A$2:$G$131,5,FALSE),"——") -> 67 | T46: 4+
A47: 46 | B47: D2-20 | C47: 14# | D47: 66.02 | E47: 2.9 | F47: 0 | G47: 0 | H47: 0 | I47: 0.69 | J47: 6.38 | K47: 0 | L47: 0 | M47: 2.57 | N47: 0.06 | O47: 1.15 | P47: 5.4 | Q47: 1.91 | R47: =IFERROR(VLOOKUP($B47&"|"&$C47,测试原始数据!$A$2:$G$131,4,FALSE),"——") -> 16.595 | S47: =IFERROR(VLOOKUP($B47&"|"&$C47,测试原始数据!$A$2:$G$131,5,FALSE),"——") -> 40 | T47: 3
A48: 47 | B48: D2-21 | C48: 14# | D48: 65.99 | E48: 0.7 | F48: 10.62 | G48: 0.34 | H48: 5.86 | I48: 0 | J48: 0 | K48: 2.77 | L48: 0 | M48: 3.54 | N48: 0.06 | O48: 12.64 | P48: 2.76 | Q48: 2.76 | R48: =IFERROR(VLOOKUP($B48&"|"&$C48,测试原始数据!$A$2:$G$131,4,FALSE),"——") -> 20.49 | S48: =IFERROR(VLOOKUP($B48&"|"&$C48,测试原始数据!$A$2:$G$131,5,FALSE),"——") -> 85 | T48: 4+
A49: 48 | B49: D2-22 | C49: 14# | D49: 65.98 | E49: 2.89 | F49: 0 | G49: 0.13 | H49: 6.59 | I49: 7.29 | J49: 0 | K49: 0 | L49: 0 | M49: 2.97 | N49: 0.06 | O49: 4.81 | P49: 2.97 | Q49: 0.96 | R49: =IFERROR(VLOOKUP($B49&"|"&$C49,测试原始数据!$A$2:$G$131,4,FALSE),"——") -> 20.255 | S49: =IFERROR(VLOOKUP($B49&"|"&$C49,测试原始数据!$A$2:$G$131,5,FALSE),"——") -> 183 | T49: 2
A50: 49 | B50: D2-23 | C50: 14# | D50: 65.98 | E50: 0.6 | F50: 11.03 | G50: 0 | H50: 0.54 | I50: 4.95 | J50: 0 | K50: 0 | L50: 0 | M50: 1.26 | N50: 0.06 | O50: 11.62 | P50: 1.78 | Q50: 0 | R50: =IFERROR(VLOOKUP($B50&"|"&$C50,测试原始数据!$A$2:$G$131,4,FALSE),"——") -> 16.445 | S50: =IFERROR(VLOOKUP($B50&"|"&$C50,测试原始数据!$A$2:$G$131,5,FALSE),"——") -> 16
A51: 50 | B51: D2-24 | C51: 14# | D51: 65.73 | E51: 0.91 | F51: 0 | G51: 0 | H51: 1.84 | I51: 4.91 | J51: 4.51 | K51: 0 | L51: 0 | M51: 1.73 | N51: 0.06 | O51: 1.95 | P51: 4.39 | Q51: 1.46 | R51: =IFERROR(VLOOKUP($B51&"|"&$C51,测试原始数据!$A$2:$G$131,4,FALSE),"——") -> 17.59 | S51: =IFERROR(VLOOKUP($B51&"|"&$C51,测试原始数据!$A$2:$G$131,5,FALSE),"——") -> 78 | T51: 3
A52: 51 | B52: D2-24 | C52: 10# | D52: 65.73 | E52: 0.91 | F52: 0 | G52: 0 | H52: 1.84 | I52: 4.91 | J52: 4.51 | K52: 0 | L52: 0 | M52: 1.73 | N52: 0.06 | O52: 1.95 | P52: 4.39 | Q52: 1.46 | R52: =IFERROR(VLOOKUP($B52&"|"&$C52,测试原始数据!$A$2:$G$131,4,FALSE),"——") -> 18.453333 | S52: =IFERROR(VLOOKUP($B52&"|"&$C52,测试原始数据!$A$2:$G$131,5,FALSE),"——") -> 60 | T52: 3
A53: 52 | B53: D2-24 | C53: 18# | D53: 65.73 | E53: 0.91 | F53: 0 | G53: 0 | H53: 1.84 | I53: 4.91 | J53: 4.51 | K53: 0 | L53: 0 | M53: 1.73 | N53: 0.06 | O53: 1.95 | P53: 4.39 | Q53: 1.46 | R53: =IFERROR(VLOOKUP($B53&"|"&$C53,测试原始数据!$A$2:$G$131,4,FALSE),"——") -> 14.743333 | S53: =IFERROR(VLOOKUP($B53&"|"&$C53,测试原始数据!$A$2:$G$131,5,FALSE),"——") -> 63 | T53: 2
...

Sheet 换算明细
A1: 复配ID | B1: 来源配方 | C1: 复配取样量(g) | D1: 来源配方总质量(g) | E1: 源IR190 | F1: 源RF401 | G1: 源RF160 | H1: 源IR809 55% | I1: 源RF516 | J1: 源RF950 | K1: 源RF956 | L1: 源RH601 | M1: 源住友55754G | N1: 源1510蜡25%工作液 | O1: 源AZ088 | P1: 源外加正丁醇 | Q1: 源补加混合液 | R1: 源10%酸工作液 | S1: 贡献IR190 | T1: 贡献RF401 | U1: 贡献RF160 | V1: 贡献IR809 55% | W1: 贡献RF516 | X1: 贡献RF950 | Y1: 贡献RF956 | Z1: 贡献RH601 | AA1: 贡献住友55754G | AB1: 贡献1510蜡25%工作液 | AC1: 贡献AZ088 | AD1: 贡献外加正丁醇 | AE1: 贡献补加混合液 | AF1: 贡献10%酸工作液 | AG1: 缩放系数(至IR190=66g)
A2: C4-1 | B2: D4-1 | C2: 37.07 | D2: =SUM(E2:R2) -> 115.98 | E2: 65.97 | F2: 1.42 | G2: 6.46 | H2: 0.65 | I2: 7 | J2: 8.98 | K2: 0 | L2: 1.26 | M2: 1.98 | N2: 3.09 | O2: 0.06 | P2: 11.84 | Q2: 5.16 | R2: 2.11 | S2: =C2/D2*E2 -> 21.0856 | T2: =C2/D2*F2 -> 0.45386618 | U2: =C2/D2*G2 -> 2.0647715 | V2: =C2/D2*H2 -> 0.20775565 | W2: =C2/D2*I2 -> 2.2373685 | X2: =C2/D2*J2 -> 2.8702242 | Y2: =C2/D2*K2 -> 0 | Z2: =C2/D2*L2 -> 0.40272633 | AA2: =C2/D2*M2 -> 0.63285566 | AB2: =C2/D2*N2 -> 0.98763839 | AC2: =C2/D2*O2 -> 0.019177444 | AD2: =C2/D2*P2 -> 3.784349 | AE2: =C2/D2*Q2 -> 1.6492602 | AF2: =C2/D2*R2 -> 0.67440679 | AG2: =66/SUMIF($A$2:$A$67,A2,$S$2:$S$67) -> 1.546083
A3: C4-1 | B3: D4-2 | C3: 40.18 | D3: =SUM(E3:R3) -> 122.83 | E3: 66.04 | F3: 0 | G3: 14.09 | H3: 0.32 | I3: 0 | J3: 1.3 | K3: 8.86 | L3: 3.38 | M3: 0 | N3: 3.64 | O3: 0.06 | P3: 4.85 | Q3: 17.6 | R3: 2.69 | S3: =C3/D3*E3 -> 21.602924 | T3: =C3/D3*F3 -> 0 | U3: =C3/D3*G3 -> 4.6091036 | V3: =C3/D3*H3 -> 0.10467801 | W3: =C3/D3*I3 -> 0 | X3: =C3/D3*J3 -> 0.42525442 | Y3: =C3/D3*K3 -> 2.8982724 | Z3: =C3/D3*L3 -> 1.1056615 | AA3: =C3/D3*M3 -> 0 | AB3: =C3/D3*N3 -> 1.1907124 | AC3: =C3/D3*O3 -> 0.019627127 | AD3: =C3/D3*P3 -> 1.5865261 | AE3: =C3/D3*Q3 -> 5.7572906 | AF3: =C3/D3*R3 -> 0.87994952 | AG3: =66/SUMIF($A$2:$A$67,A3,$S$2:$S$67) -> 1.546083
A4: C4-2 | B4: D4-2 | C4: 44.91 | D4: =SUM(E4:R4) -> 122.83 | E4: 66.04 | F4: 0 | G4: 14.09 | H4: 0.32 | I4: 0 | J4: 1.3 | K4: 8.86 | L4: 3.38 | M4: 0 | N4: 3.64 | O4: 0.06 | P4: 4.85 | Q4: 17.6 | R4: 2.69 | S4: =C4/D4*E4 -> 24.146026 | T4: =C4/D4*F4 -> 0 | U4: =C4/D4*G4 -> 5.1516885 | V4: =C4/D4*H4 -> 0.11700073 | W4: =C4/D4*I4 -> 0 | X4: =C4/D4*J4 -> 0.47531548 | Y4: =C4/D4*K4 -> 3.2394578 | Z4: =C4/D4*L4 -> 1.2358202 | AA4: =C4/D4*M4 -> 0 | AB4: =C4/D4*N4 -> 1.3308833 | AC4: =C4/D4*O4 -> 0.021937637 | AD4: =C4/D4*P4 -> 1.7732924 | AE4: =C4/D4*Q4 -> 6.4350403 | AF4: =C4/D4*R4 -> 0.98353741 | AG4: =66/SUMIF($A$2:$A$67,A4,$S$2:$S$67) -> 1.4639322
A5: C4-2 | B5: D4-3 | C5: 34.05 | D5: =SUM(E5:R5) -> 107.64 | E5: 66.19 | F5: 0 | G5: 5.2 | H5: 0 | I5: 7.9 | J5: 7.81 | K5: 3.12 | L5: 0 | M5: 0 | N5: 1.51 | O5: 0.06 | P5: 8.8 | Q5: 6.53 | R5: 0.52 | S5: =C5/D5*E5 -> 20.93803 | T5: =C5/D5*F5 -> 0 | U5: =C5/D5*G5 -> 1.6449275 | V5: =C5/D5*H5 -> 0 | W5: =C5/D5*I5 -> 2.4990245 | X5: =C5/D5*J5 -> 2.4705546 | Y5: =C5/D5*K5 -> 0.98695652 | Z5: =C5/D5*L5 -> 0 | AA5: =C5/D5*M5 -> 0 | AB5: =C5/D5*N5 -> 0.47766165 | AC5: =C5/D5*O5 -> 0.018979933 | AD5: =C5/D5*P5 -> 2.7837235 | AE5: =C5/D5*Q5 -> 2.0656494 | AF5: =C5/D5*R5 -> 0.16449275 | AG5: =66/SUMIF($A$2:$A$67,A5,$S$2:$S$67) -> 1.4639322
A6: C4-3 | B6: D4-3 | C6: 45.88 | D6: =SUM(E6:R6) -> 107.64 | E6: 66.19 | F6: 0 | G6: 5.2 | H6: 0 | I6: 7.9 | J6: 7.81 | K6: 3.12 | L6: 0 | M6: 0 | N6: 1.51 | O6: 0.06 | P6: 8.8 | Q6: 6.53 | R6: 0.52 | S6: =C6/D6*E6 -> 28.212534 | T6: =C6/D6*F6 -> 0 | U6: =C6/D6*G6 -> 2.2164251 | V6: =C6/D6*H6 -> 0 | W6: =C6/D6*I6 -> 3.3672612 | X6: =C6/D6*J6 -> 3.3289 | Y6: =C6/D6*K6 -> 1.3298551 | Z6: =C6/D6*L6 -> 0 | AA6: =C6/D6*M6 -> 0 | AB6: =C6/D6*N6 -> 0.64361576 | AC6: =C6/D6*O6 -> 0.025574136 | AD6: =C6/D6*P6 -> 3.7508733 | AE6: =C6/D6*Q6 -> 2.7833185 | AF6: =C6/D6*R6 -> 0.22164251 | AG6: =66/SUMIF($A$2:$A$67,A6,$S$2:$S$67) -> 1.320941
A7: C4-3 | B7: D4-4 | C7: 40.8 | D7: =SUM(E7:R7) -> 123.44 | E7: 65.81 | F7: 3.59 | G7: 0 | H7: 0.13 | I7: 7.98 | J7: 7.9 | K7: 6.36 | L7: 4.31 | M7: 1.55 | N7: 2.95 | O7: 0.06 | P7: 12.39 | Q7: 9.6 | R7: 0.81 | S7: =C7/D7*E7 -> 21.751847 | T7: =C7/D7*F7 -> 1.1865846 | U7: =C7/D7*G7 -> 0 | V7: =C7/D7*H7 -> 0.042968244 | W7: =C7/D7*I7 -> 2.6375891 | X7: =C7/D7*J7 -> 2.6111471 | Y7: =C7/D7*K7 -> 2.1021387 | Z7: =C7/D7*L7 -> 1.4245625 | AA7: =C7/D7*M7 -> 0.51231367 | AB7: =C7/D7*N7 -> 0.97504861 | AC7: =C7/D7*O7 -> 0.019831497 | AD7: =C7/D7*P7 -> 4.0952041 | AE7: =C7/D7*Q7 -> 3.1730395 | AF7: =C7/D7*R7 -> 0.26772521 | AG7: =66/SUMIF($A$2:$A$67,A7,$S$2:$S$67) -> 1.320941
A8: C4-4 | B8: D4-4 | C8: 57 | D8: =SUM(E8:R8) -> 123.44 | E8: 65.81 | F8: 3.59 | G8: 0 | H8: 0.13 | I8: 7.98 | J8: 7.9 | K8: 6.36 | L8: 4.31 | M8: 1.55 | N8: 2.95 | O8: 0.06 | P8: 12.39 | Q8: 9.6 | R8: 0.81 | S8: =C8/D8*E8 -> 30.38861 | T8: =C8/D8*F8 -> 1.6577285 | U8: =C8/D8*G8 -> 0 | V8: =C8/D8*H8 -> 0.060029164 | W8: =C8/D8*I8 -> 3.6848671 | X8: =C8/D8*J8 -> 3.6479261 | Y8: =C8/D8*K8 -> 2.9368114 | Z8: =C8/D8*L8 -> 1.9901977 | AA8: =C8/D8*M8 -> 0.71573234 | AB8: =C8/D8*N8 -> 1.3622003 | AC8: =C8/D8*O8 -> 0.027705768 | AD8: =C8/D8*P8 -> 5.7212411 | AE8: =C8/D8*Q8 -> 4.4329229 | AF8: =C8/D8*R8 -> 0.37402787 | AG8: =66/SUMIF($A$2:$A$67,A8,$S$2:$S$67) -> 1.270498
A9: C4-4 | B9: D4-5 | C9: 36.56 | D9: =SUM(E9:R9) -> 112.26 | E9: 66.2 | F9: 3.26 | G9: 9.83 | H9: 0 | I9: 1.92 | J9: 7.36 | K9: 0 | L9: 0.87 | M9: 1.37 | N9: 2.88 | O9: 0.06 | P9: 5.3 | Q9: 13.21 | R9: 0 | S9: =C9/D9*E9 -> 21.559523 | T9: =C9/D9*F9 -> 1.0616925 | U9: =C9/D9*G9 -> 3.2013611 | V9: =C9/D9*H9 -> 0 | W9: =C9/D9*I9 -> 0.62529129 | X9: =C9/D9*J9 -> 2.3969499 | Y9: =C9/D9*K9 -> 0 | Z9: =C9/D9*L9 -> 0.28333511 | AA9: =C9/D9*M9 -> 0.44617139 | AB9: =C9/D9*N9 -> 0.93793693 | AC9: =C9/D9*O9 -> 0.019540353 | AD9: =C9/D9*P9 -> 1.7260645 | AE9: =C9/D9*Q9 -> 4.3021343 | AF9: =C9/D9*R9 -> 0 | AG9: =66/SUMIF($A$2:$A$67,A9,$S$2:$S$67) -> 1.270498
A10: C4-5 | B10: D4-5 | C10: 44.13 | D10: =SUM(E10:R10) -> 112.26 | E10: 66.2 | F10: 3.26 | G10: 9.83 | H10: 0 | I10: 1.92 | J10: 7.36 | K10: 0 | L10: 0.87 | M10: 1.37 | N10: 2.88 | O10: 0.06 | P10: 5.3 | Q10: 13.21 | R10: 0 | S10: =C10/D10*E10 -> 26.02357 | T10: =C10/D10*F10 -> 1.2815232 | U10: =C10/D10*G10 -> 3.864225 | V10: =C10/D10*H10 -> 0 | W10: =C10/D10*I10 -> 0.75476216 | X10: =C10/D10*J10 -> 2.8932549 | Y10: =C10/D10*K10 -> 0 | Z10: =C10/D10*L10 -> 0.3420016 | AA10: =C10/D10*M10 -> 0.53855425 | AB10: =C10/D10*N10 -> 1.1321432 | AC10: =C10/D10*O10 -> 0.023586317 | AD10: =C10/D10*P10 -> 2.083458 | AE10: =C10/D10*Q10 -> 5.1929209 | AF10: =C10/D10*R10 -> 0 | AG10: =66/SUMIF($A$2:$A$67,A10,$S$2:$S$67) -> 1.2402002
A11: C4-5 | B11: D4-6 | C11: 43.14 | D11: =SUM(E11:R11) -> 104.75 | E11: 66.03 | F11: 2.59 | G11: 0 | H11: 0.41 | I11: 5.11 | J11: 4.12 | K11: 7.36 | L11: 0 | M11: 1.9 | N11: 1.05 | O11: 0.06 | P11: 11.35 | Q11: 4.03 | R11: 0.74 | S11: =C11/D11*E11 -> 27.193644 | T11: =C11/D11*F11 -> 1.0666597 | U11: =C11/D11*G11 -> 0 | V11: =C11/D11*H11 -> 0.16885346 | W11: =C11/D11*I11 -> 2.1044907 | X11: =C11/D11*J11 -> 1.6967714 | Y11: =C11/D11*K11 -> 3.0311255 | Z11: =C11/D11*L11 -> 0 | AA11: =C11/D11*M11 -> 0.78249165 | AB11: =C11/D11*N11 -> 0.43242959 | AC11: =C11/D11*O11 -> 0.024710263 | AD11: =C11/D11*P11 -> 4.674358 | AE11: =C11/D11*Q11 -> 1.659706 | AF11: =C11/D11*R11 -> 0.3047599 | AG11: =66/SUMIF($A$2:$A$67,A11,$S$2:$S$67) -> 1.2402002
A12: C4-6 | B12: D4-6 | C12: 44.7 | D12: =SUM(E12:R12) -> 104.75 | E12: 66.03 | F12: 2.59 | G12: 0 | H12: 0.41 | I12: 5.11 | J12: 4.12 | K12: 7.36 | L12: 0 | M12: 1.9 | N12: 1.05 | O12: 0.06 | P12: 11.35 | Q12: 4.03 | R12: 0.74 | S12: =C12/D12*E12 -> 28.177002 | T12: =C12/D12*F12 -> 1.1052315 | U12: =C12/D12*G12 -> 0 | V12: =C12/D12*H12 -> 0.17495943 | W12: =C12/D12*I12 -> 2.1805919 | X12: =C12/D12*J12 -> 1.7581289 | Y12: =C12/D12*K12 -> 3.1407351 | Z12: =C12/D12*L12 -> 0 | AA12: =C12/D12*M12 -> 0.81078759 | AB12: =C12/D12*N12 -> 0.44806683 | AC12: =C12/D12*O12 -> 0.025603819 | AD12: =C12/D12*P12 -> 4.843389 | AE12: =C12/D12*Q12 -> 1.7197232 | AF12: =C12/D12*R12 -> 0.31578043 | AG12: =66/SUMIF($A$2:$A$67,A12,$S$2:$S$67) -> 1.2517116
A13: C4-6 | B13: D4-7 | C13: 44.7 | D13: =SUM(E13:R13) -> 120.24 | E13: 66.04 | F13: 0.87 | G13: 11.52 | H13: 0 | I13: 7.77 | J13: 3.76 | K13: 0 | L13: 2.88 | M13: 1.77 | N13: 3 | O13: 0.06 | P13: 11.36 | Q13: 9.2 | R13: 2.01 | S13: =C13/D13*E13 -> 24.550798 | T13: =C13/D13*F13 -> 0.32342814 | U13: =C13/D13*G13 -> 4.2826347 | V13: =C13/D13*H13 -> 0 | W13: =C13/D13*I13 -> 2.8885479 | X13: =C13/D13*J13 -> 1.3978044 | Y13: =C13/D13*K13 -> 0 | Z13: =C13/D13*L13 -> 1.0706587 | AA13: =C13/D13*M13 -> 0.65800898 | AB13: =C13/D13*N13 -> 1.1152695 | AC13: =C13/D13*O13 -> 0.022305389 | AD13: =C13/D13*P13 -> 4.2231537 | AE13: =C13/D13*Q13 -> 3.4201597 | AF13: =C13/D13*R13 -> 0.74723054 | AG13: =66/SUMIF($A$2:$A$67,A13,$S$2:$S$67) -> 1.2517116
... A67: C6-8 | B67: D6-1 | C67: 16.78 | D67: =SUM(E67:R67) -> 97.63 | E67: 66 | F67: 3.17 | G67: 6.18 | H67: 0.68 | I67: 5.77 | J67: 0 | K67: 0 | L67: 0.54 | M67: 0 | N67: 1.82 | O67: 0.06 | P67: 5.65 | Q67: 7.12 | R67: 0.64 | S67: =C67/D67*E67 -> 11.343644 | T67: =C67/D67*F67 -> 0.54483868 | U67: =C67/D67*G67 -> 1.0621776 | V67: =C67/D67*H67 -> 0.11687391 | W67: =C67/D67*I67 -> 0.99170952 | X67: =C67/D67*J67 -> 0 | Y67: =C67/D67*K67 -> 0 | Z67: =C67/D67*L67 -> 0.092811636 | AA67: =C67/D67*M67 -> 0 | AB67: =C67/D67*N67 -> 0.31280959 | AC67: =C67/D67*O67 -> 0.010312404 | AD67: =C67/D67*P67 -> 0.97108471 | AE67: =C67/D67*Q67 -> 1.2237386 | AF67: =C67/D67*R67 -> 0.10999898 | AG67: =66/SUMIF($A$2:$A$67,A67,$S$2:$S$67) -> 2.2689801

Sheet 测试原始数据
A1: 匹配键 | B1: 样本ID | C1: 线棒号 | D1: T弯平均(mm) | E1: MEK擦拭(次) | F1: 水煮（等级） | G1: 来源文件
A2: D1-1|14# | B2: D1-1 | C2: 14# | D2: 17.415 | E2: 9 | F2: 4 | G2: D1测试数据.xlsx
A3: D1-2|14# | B3: D1-2 | C3: 14# | D3: 19.22 | E3: 161 | F3: 2 | G3: D1测试数据.xlsx
A4: D1-3|14# | B4: D1-3 | C4: 14# | D4: 15.69 | E4: 10 | F4: 4 | G4: D1测试数据.xlsx
A5: D1-4|14# | B5: D1-4 | C5: 14# | D5: 18.05 | E5: 98 | F5: 3 | G5: D1测试数据.xlsx
A6: D1-5|14# | B6: D1-5 | C6: 14# | D6: 20.8 | E6: 300+ | F6: 3 | G6: D1测试数据.xlsx
A7: D1-6|14# | B7: D1-6 | C7: 14# | D7: 14.365 | E7: 5 | F7: 4 | G7: D1测试数据.xlsx
A8: D1-7|14# | B8: D1-7 | C8: 14# | D8: 16.535 | E8: 32 | F8: 4 | G8: D1测试数据.xlsx
A9: D1-8|14# | B9: D1-8 | C9: 14# | D9: 15.225 | E9: 4 | F9: 4 | G9: D1测试数据.xlsx
A10: D1-9|14# | B10: D1-9 | C10: 14# | D10: 22.32 | E10: 172 | F10: 2 | G10: D1测试数据.xlsx
A11: D1-10|14# | B11: D1-10 | C11: 14# | D11: 16.09 | E11: 95 | F11: 4 | G11: D1测试数据.xlsx
A12: D1-11|14# | B12: D1-11 | C12: 14# | D12: 17.145 | E12: 33 | F12: 2 | G12: D1测试数据.xlsx
A13: D1-12|14# | B13: D1-12 | C13: 14# | D13: 14.46 | E13: 11 | F13: 4 | G13: D1测试数据.xlsx
A14: D1-13|14# | B14: D1-13 | C14: 14# | D14: 15.5 | E14: 20 | F14: 4 | G14: D1测试数据.xlsx
A15: D1-14|14# | B15: D1-14 | C15: 14# | D15: 18.25 | E15: 87 | F15: 2 | G15: D1测试数据.xlsx
A16: D1-15|14# | B16: D1-15 | C16: 14# | D16: 15.5 | E16: 80 | F16: 3 | G16: D1测试数据.xlsx
A17: D1-16|14# | B17: D1-16 | C17: 14# | D17: 14.45 | E17: 32 | F17: 1 | G17: D1测试数据.xlsx
A18: D1-17|14# | B18: D1-17 | C18: 14# | D18: 21.705 | E18: 160 | F18: 3 | G18: D1测试数据.xlsx
... A27: D1-24|18# | B27: D1-24 | C27: 18# | D27: 16.72 | E27: 125 | F27: 4 | G27: D1测试数据.xlsx
A28: D2-1|14# | B28: D2-1 | C28: 14# | D28: 19.32 | E28: 68 | F28: —— | G28: D2测试数据.xlsx
A29: D2-2|14# | B29: D2-2 | C29: 14# | D29: 18.95 | E29: 76 | F29: —— | G29: D2测试数据.xlsx
A30: D2-3|14# | B30: D2-3 | C30: 14# | D30: 20.57 | E30: 60 | F30: —— | G30: D2测试数据.xlsx
A31: D2-4|14# | B31: D2-4 | C31: 14# | D31: 14.695 | E31: 9 | F31: —— | G31: D2测试数据.xlsx
A32: D2-5|14# | B32: D2-5 | C32: 14# | D32: 14.215 | E32: 40 | F32: —— | G32: D2测试数据.xlsx
A33: D2-6|14# | B33: D2-6 | C33: 14# | D33: 20.335 | E33: 112 | F33: —— | G33: D2测试数据.xlsx
A34: D2-7|14# | B34: D2-7 | C34: 14# | D34: 12.485 | E34: 79 | F34: —— | G34: D2测试数据.xlsx
A35: D2-8|14# | B35: D2-8 | C35: 14# | D35: 20.9 | E35: 131 | F35: —— | G35: D2测试数据.xlsx
A36: D2-9|14# | B36: D2-9 | C36: 14# | D36: 15.53 | E36: 5 | F36: —— | G36: D2测试数据.xlsx
A37: D2-10|14# | B37: D2-10 | C37: 14# | D37: 14.995 | E37: 60 | F37: —— | G37: D2测试数据.xlsx
A38: D2-11|14# | B38: D2-11 | C38: 14# | D38: 17.04 | E38: 65 | F38: —— | G38: D2测试数据.xlsx
A39: D2-12|14# | B39: D2-12 | C39: 14# | D39: 17.89 | E39: 50 | F39: —— | G39: D2测试数据.xlsx
... A131: C5-16|18# | B131: C5-16 | C131: 18# | D131: 17.76 | E131: 60 | F131: —— | G131: D5测试数据.xlsx
