Workbook

Sheet 使用说明
B1: 终极版涂料配方-性能数据集模板 v3
B3: 一、模板定位
B6: 二、v3 核心改进
B12: 三、工作表结构
B21: 四、填写流程
B27: 五、系列编码（关键建模技术）
B32: 六、标签补充闭环（解决缺标签问题）
B38: 七、关键规则

Sheet 体系配置
A1: 体系名称 | B1: 固化机制 | C1: 典型树脂类型 | D1: 目标属性 | E1: 单位 | F1: 方向 | G1: 数据类型 | H1: 适用标准/说明
A2: 环氧酚醛 | B2: 环氧-酚醛缩合 | C2: 环氧/酚醛 | D2: T弯 | E2: mm | F2: 越低越好 | G2: 连续 | H2: 杯突/弯曲试验
A3: 环氧酚醛 | B3: 环氧-酚醛缩合 | C3: 环氧/酚醛 | D3: MEK擦拭 | E3: 次 | F3: 越高越好 | G3: 计数 | H3: MEK溶剂擦拭
A4: 环氧酚醛 | B4: 环氧-酚醛缩合 | C4: 环氧/酚醛 | D4: 水煮等级 | E4: 级 | F4: 越低越好 | G4: 等级 | H4: 1-5级水煮
A5: 有机 | B5: 羟基-氨基树脂 | C5: 丙烯酸/乙烯基/环氧 | D5: T弯 | E5: mm | F5: 越低越好 | G5: 连续 | H5: 弯曲试验
A6: 有机 | B6: 羟基-氨基树脂 | C6: 丙烯酸/乙烯基/环氧 | D6: MEK擦拭 | E6: 次 | F6: 越高越好 | G6: 计数 | H6: MEK溶剂擦拭
A7: 有机 | B7: 羟基-氨基树脂 | C7: 丙烯酸/乙烯基/环氧 | D7: 附着力 | E7: 级 | F7: 越高越好 | G7: 等级 | H7: 划格试验
A8: 聚酯 | B8: 羟基-氨基树脂 | C8: 聚酯 | D8: T弯 | E8: mm | F8: 越低越好 | G8: 连续 | H8: 弯曲试验
A9: 聚酯 | B9: 羟基-氨基树脂 | C9: 聚酯 | D9: MEK擦拭 | E9: 次 | F9: 越高越好 | G9: 计数 | H9: MEK溶剂擦拭
A10: 聚酯 | B10: 羟基-氨基树脂 | C10: 聚酯 | D10: 水煮等级 | E10: 级 | F10: 越低越好 | G10: 等级 | H10: 1-5级水煮
A11: 聚氨酯 | B11: 羟基-异氰酸酯 | C11: 聚酯/丙烯酸/聚氨酯 | D11: T弯 | E11: mm | F11: 越低越好 | G11: 连续 | H11: 弯曲试验
A12: 聚氨酯 | B12: 羟基-异氰酸酯 | C12: 聚酯/丙烯酸/聚氨酯 | D12: MEK擦拭 | E12: 次 | F12: 越高越好 | G12: 计数 | H12: MEK溶剂擦拭
... A17: 环氧胺 | B17: 环氧-胺加成 | C17: 环氧 | D17: MEK擦拭 | E17: 次 | F17: 越高越好 | G17: 计数 | H17: MEK溶剂擦拭

Sheet 原料主数据
A1: 原料代码 | B1: 原料名称 | C1: 所属体系 | D1: 角色 | E1: 树脂类型 | F1: SMILES | G1: 描述符状态 | H1: 固含NV(%) | I1: 密度(g/cm³) | J1: 分子量(g/mol) | K1: 环氧当量EEW(g/eq) | L1: 酸值AV(mgKOH/g) | M1: 羟值OHV(mgKOH/g) | N1: 胺值(mgKOH/g) | O1: 官能度 | P1: Tg(℃) | Q1: 沸点(℃) | R1: 闪点(℃) | S1: Hansen δD | T1: Hansen δP | U1: Hansen δH | V1: 极性指数 | W1: 相对挥发速率 | X1: C(%) | Y1: H(%) | Z1: O(%) | AA1: N(%) | AB1: S(%) | AC1: Cl(%) | AD1: 环氧基(mol/100g) | AE1: 羟基(mol/100g) | AF1: 羧基(mol/100g) | AG1: 酯基(mol/100g) | AH1: 胺基(mol/100g) | AI1: 酰胺(mol/100g) | AJ1: 芳香环(mol/100g) | AK1: 醚键(mol/100g) | AL1: 蜡含量(%) | AM1: 颜料含量(%) | AN1: 数据来源 | AO1: 备注
A2: IR190 | B2: 9型环氧树脂36%固含 | C2: 环氧酚醛 | D2: 树脂 | E2: 环氧 | G2: 专有估算 | H2: 36 | I2: 1 | J2: 1400 | K2: 2640 | L2: 0.5 | M2: 30 | N2: 0 | O2: 2 | P2: 70 | Q2: 250 | R2: 100 | S2: 18.5 | T2: 6 | U2: 8.5 | V2: 3 | W2: 0 | X2: 72 | Y2: 7 | Z2: 20 | AA2: 0 | AB2: 0 | AC2: 0 | AD2: 0.038 | AE2: 0.018 | AF2: 0.001 | AG2: 0.01 | AH2: 0 | AI2: 0 | AJ2: 0.4 | AK2: 0.15 | AL2: 0 | AM2: 0 | AN2: 类别典型值/文件信息
A3: IR809 | B3: 环氧树脂55%固含 | C3: 环氧酚醛 | D3: 树脂 | E3: 环氧 | G3: 专有估算 | H3: 55 | I3: 1.02 | J3: 1200 | K3: 1600 | L3: 0.5 | M3: 35 | N3: 0 | O3: 2 | P3: 65 | Q3: 250 | R3: 100 | S3: 18.3 | T3: 6.2 | U3: 8.8 | V3: 3.1 | W3: 0 | X3: 71 | Y3: 7 | Z3: 21 | AA3: 0 | AB3: 0 | AC3: 0 | AD3: 0.062 | AE3: 0.021 | AF3: 0.001 | AG3: 0.01 | AH3: 0 | AI3: 0 | AJ3: 0.38 | AK3: 0.16 | AL3: 0 | AM3: 0 | AN3: 类别典型值/文件信息
A4: 住友55754G | B4: 住友环氧树脂 | C4: 环氧酚醛 | D4: 树脂 | E4: 环氧 | G4: 专有估算 | H4: 100 | I4: 1.15 | J4: 1000 | K4: 950 | L4: 0.3 | M4: 40 | N4: 0 | O4: 2 | P4: 75 | Q4: 300 | R4: 150 | S4: 18.8 | T4: 6 | U4: 8.2 | V4: 3 | W4: 0 | X4: 73 | Y4: 7 | Z4: 19 | AA4: 0 | AB4: 0 | AC4: 0 | AD4: 0.105 | AE4: 0.024 | AF4: 0.001 | AG4: 0.01 | AH4: 0 | AI4: 0 | AJ4: 0.42 | AK4: 0.15 | AL4: 0 | AM4: 0 | AN4: 类别典型值/文件信息
A5: IR191 | B5: IR191 | C5: 通用 | D5: 树脂 | E5: 环氧 | G5: 专有估算 | H5: 36 | I5: 1 | J5: 1400 | K5: 2650 | L5: 0.5 | M5: 30 | N5: 0 | O5: 2 | P5: 70 | Q5: 250 | R5: 100 | S5: 18.5 | T5: 6 | U5: 8.5 | V5: 3 | W5: 0 | X5: 72 | Y5: 7 | Z5: 20 | AA5: 0 | AB5: 0 | AC5: 0 | AD5: 0.038 | AE5: 0.018 | AF5: 0.001 | AG5: 0.01 | AH5: 0 | AI5: 0 | AJ5: 0.4 | AK5: 0.15 | AL5: 0 | AM5: 0 | AN5: 类别典型值/文件信息
A6: IR170 | B6: IR170 | C6: 通用 | D6: 树脂 | E6: 环氧 | G6: 专有估算 | H6: 50 | I6: 1.02 | J6: 1300 | K6: 1800 | L6: 0.5 | M6: 32 | N6: 0 | O6: 2 | P6: 68 | Q6: 250 | R6: 100 | S6: 18.4 | T6: 6.1 | U6: 8.6 | V6: 3 | W6: 0 | X6: 72 | Y6: 7 | Z6: 20 | AA6: 0 | AB6: 0 | AC6: 0 | AD6: 0.056 | AE6: 0.019 | AF6: 0.001 | AG6: 0.01 | AH6: 0 | AI6: 0 | AJ6: 0.4 | AK6: 0.15 | AL6: 0 | AM6: 0 | AN6: 类别典型值/文件信息
A7: IR877 | B7: 环氧树脂 | C7: 有机 | D7: 树脂 | E7: 环氧 | G7: 专有估算 | H7: 60 | I7: 1.03 | J7: 1200 | K7: 1500 | L7: 0.5 | M7: 35 | N7: 0 | O7: 2 | P7: 66 | Q7: 250 | R7: 100 | S7: 18.3 | T7: 6.2 | U7: 8.7 | V7: 3.1 | W7: 0 | X7: 71 | Y7: 7 | Z7: 21 | AA7: 0 | AB7: 0 | AC7: 0 | AD7: 0.067 | AE7: 0.021 | AF7: 0.001 | AG7: 0.01 | AH7: 0 | AI7: 0 | AJ7: 0.38 | AK7: 0.16 | AL7: 0 | AM7: 0 | AN7: 类别典型值/文件信息
A8: IR909 | B8: 环氧树脂 | C8: 聚酯 | D8: 树脂 | E8: 环氧 | G8: 专有估算 | H8: 60 | I8: 1.03 | J8: 1200 | K8: 1500 | L8: 0.5 | M8: 35 | N8: 0 | O8: 2 | P8: 66 | Q8: 250 | R8: 100 | S8: 18.3 | T8: 6.2 | U8: 8.7 | V8: 3.1 | W8: 0 | X8: 71 | Y8: 7 | Z8: 21 | AA8: 0 | AB8: 0 | AC8: 0 | AD8: 0.067 | AE8: 0.021 | AF8: 0.001 | AG8: 0.01 | AH8: 0 | AI8: 0 | AJ8: 0.38 | AK8: 0.16 | AL8: 0 | AM8: 0 | AN8: 类别典型值/文件信息
A9: IR557 | B9: 环氧树脂 | C9: 聚酯 | D9: 树脂 | E9: 环氧 | G9: 专有估算 | H9: 60 | I9: 1.03 | J9: 1200 | K9: 1500 | L9: 0.5 | M9: 35 | N9: 0 | O9: 2 | P9: 66 | Q9: 250 | R9: 100 | S9: 18.3 | T9: 6.2 | U9: 8.7 | V9: 3.1 | W9: 0 | X9: 71 | Y9: 7 | Z9: 21 | AA9: 0 | AB9: 0 | AC9: 0 | AD9: 0.067 | AE9: 0.021 | AF9: 0.001 | AG9: 0.01 | AH9: 0 | AI9: 0 | AJ9: 0.38 | AK9: 0.16 | AL9: 0 | AM9: 0 | AN9: 类别典型值/文件信息
A10: R170M | B10: 环氧树脂 | C10: 聚酯 | D10: 树脂 | E10: 环氧 | G10: 专有估算 | H10: 60 | I10: 1.03 | J10: 1200 | K10: 1500 | L10: 0.5 | M10: 35 | N10: 0 | O10: 2 | P10: 66 | Q10: 250 | R10: 100 | S10: 18.3 | T10: 6.2 | U10: 8.7 | V10: 3.1 | W10: 0 | X10: 71 | Y10: 7 | Z10: 21 | AA10: 0 | AB10: 0 | AC10: 0 | AD10: 0.067 | AE10: 0.021 | AF10: 0.001 | AG10: 0.01 | AH10: 0 | AI10: 0 | AJ10: 0.38 | AK10: 0.16 | AL10: 0 | AM10: 0 | AN10: 类别典型值/文件信息
A11: IR868 | B11: 环氧树脂 | C11: 聚酯 | D11: 树脂 | E11: 环氧 | G11: 专有估算 | H11: 60 | I11: 1.03 | J11: 1200 | K11: 1500 | L11: 0.5 | M11: 35 | N11: 0 | O11: 2 | P11: 66 | Q11: 250 | R11: 100 | S11: 18.3 | T11: 6.2 | U11: 8.7 | V11: 3.1 | W11: 0 | X11: 71 | Y11: 7 | Z11: 21 | AA11: 0 | AB11: 0 | AC11: 0 | AD11: 0.067 | AE11: 0.021 | AF11: 0.001 | AG11: 0.01 | AH11: 0 | AI11: 0 | AJ11: 0.38 | AK11: 0.16 | AL11: 0 | AM11: 0 | AN11: 类别典型值/文件信息
A12: IR842 | B12: 环氧树脂 | C12: 有机 | D12: 树脂 | E12: 环氧 | G12: 专有估算 | H12: 60 | I12: 1.03 | J12: 1200 | K12: 1500 | L12: 0.5 | M12: 35 | N12: 0 | O12: 2 | P12: 66 | Q12: 250 | R12: 100 | S12: 18.3 | T12: 6.2 | U12: 8.7 | V12: 3.1 | W12: 0 | X12: 71 | Y12: 7 | Z12: 21 | AA12: 0 | AB12: 0 | AC12: 0 | AD12: 0.067 | AE12: 0.021 | AF12: 0.001 | AG12: 0.01 | AH12: 0 | AI12: 0 | AJ12: 0.38 | AK12: 0.16 | AL12: 0 | AM12: 0 | AN12: 类别典型值/文件信息
A13: 40%50177 | B13: 环氧树脂40%固含 | C13: 有机 | D13: 树脂 | E13: 环氧 | G13: 专有估算 | H13: 40 | I13: 1.01 | J13: 1300 | K13: 2400 | L13: 0.5 | M13: 32 | N13: 0 | O13: 2 | P13: 68 | Q13: 250 | R13: 100 | S13: 18.4 | T13: 6.1 | U13: 8.6 | V13: 3 | W13: 0 | X13: 72 | Y13: 7 | Z13: 20 | AA13: 0 | AB13: 0 | AC13: 0 | AD13: 0.042 | AE13: 0.019 | AF13: 0.001 | AG13: 0.01 | AH13: 0 | AI13: 0 | AJ13: 0.4 | AK13: 0.15 | AL13: 0 | AM13: 0 | AN13: 类别典型值/文件信息
... A35: IA893 | B35: 丙烯酸树脂 | C35: 有机 | D35: 树脂 | E35: 丙烯酸 | G35: 专有估算 | H35: 50 | I35: 1.05 | J35: 15000 | K35: 0 | L35: 5 | M35: 50 | N35: 0 | O35: 1 | P35: 45 | Q35: 250 | R35: 100 | S35: 17.8 | T35: 6.5 | U35: 8.5 | V35: 3 | W35: 0 | X35: 65 | Y35: 9 | Z35: 25 | AA35: 0 | AB35: 0 | AC35: 0 | AD35: 0 | AE35: 0.03 | AF35: 0.003 | AG35: 0.3 | AH35: 0 | AI35: 0 | AJ35: 0.25 | AK35: 0.05 | AL35: 0 | AM35: 0 | AN35: 类别典型值/文件信息
A36: TM004 | B36: 乙二醇丁醚 | C36: 聚酯 | D36: 溶剂 | E36: 其他 | F36: CCCCOCCO | G36: 已计算 | H36: 0 | I36: 0.9 | J36: 118.2 | K36: 0 | L36: 0 | M36: 0 | N36: 0 | O36: 0 | P36: -70 | Q36: 171 | R36: 60 | S36: 16 | T36: 5.1 | U36: 12.3 | V36: 3.1 | W36: 0.07 | X36: 61 | Y36: 12 | Z36: 27 | AA36: 0 | AB36: 0 | AC36: 0 | AD36: 0 | AE36: 0.85 | AF36: 0 | AG36: 0 | AH36: 0 | AI36: 0 | AJ36: 0 | AK36: 0.85 | AL36: 0 | AM36: 0 | AN36: 类别典型值/文件信息
A37: 正丁醇 | B37: 正丁醇 | C37: 环氧酚醛 | D37: 溶剂 | E37: 其他 | F37: CCCCO | G37: 已计算 | H37: 0 | I37: 0.81 | J37: 74.1 | K37: 0 | L37: 0 | M37: 0 | N37: 0 | O37: 0 | P37: -90 | Q37: 117.7 | R37: 35 | S37: 15.8 | T37: 5.7 | U37: 15.8 | V37: 3.9 | W37: 0.44 | X37: 65 | Y37: 14 | Z37: 22 | AA37: 0 | AB37: 0 | AC37: 0 | AD37: 0 | AE37: 1.35 | AF37: 0 | AG37: 0 | AH37: 0 | AI37: 0 | AJ37: 0 | AK37: 0 | AL37: 0 | AM37: 0 | AN37: 类别典型值/文件信息
A38: 二甲苯 | B38: 二甲苯 | C38: 通用 | D38: 溶剂 | E38: 其他 | F38: Cc1ccccc1C | G38: 已计算 | H38: 0 | I38: 0.86 | J38: 106.2 | K38: 0 | L38: 0 | M38: 0 | N38: 0 | O38: 0 | P38: -48 | Q38: 139 | R38: 25 | S38: 17.8 | T38: 1 | U38: 3.1 | V38: 2.5 | W38: 0.7 | X38: 90 | Y38: 10 | Z38: 0 | AA38: 0 | AB38: 0 | AC38: 0 | AD38: 0 | AE38: 0 | AF38: 0 | AG38: 0 | AH38: 0 | AI38: 0 | AJ38: 1 | AK38: 0 | AL38: 0 | AM38: 0 | AN38: 类别典型值/文件信息
A39: 补加混合液 | B39: 乙二醇单丁醚:二甲苯=2:1 | C39: 环氧酚醛 | D39: 溶剂 | E39: 其他 | F39: CCCCOCCO | G39: 已计算 | H39: 0 | I39: 0.89 | J39: 114.2 | K39: 0 | L39: 0 | M39: 0 | N39: 0 | O39: 0 | P39: -63 | Q39: 160 | R39: 48 | S39: 16.6 | T39: 3.7 | U39: 9.2 | V39: 2.9 | W39: 0.28 | X39: 71 | Y39: 11 | Z39: 18 | AA39: 0 | AB39: 0 | AC39: 0 | AD39: 0 | AE39: 0.57 | AF39: 0 | AG39: 0 | AH39: 0 | AI39: 0 | AJ39: 0.33 | AK39: 0.57 | AL39: 0 | AM39: 0 | AN39: 类别典型值/文件信息
A40: TZ161 | B40: PMA溶剂 | C40: 有机 | D40: 溶剂 | E40: 其他 | F40: CC(C)OC(=O)C | G40: 已计算 | H40: 0 | I40: 0.97 | J40: 132.2 | K40: 0 | L40: 0 | M40: 0 | N40: 0 | O40: 0 | P40: -80 | Q40: 146 | R40: 42 | S40: 15.6 | T40: 5.6 | U40: 9.8 | V40: 3.4 | W40: 0.34 | X40: 55 | Y40: 9 | Z40: 36 | AA40: 0 | AB40: 0 | AC40: 0 | AD40: 0 | AE40: 0 | AF40: 0 | AG40: 0.76 | AH40: 0 | AI40: 0 | AJ40: 0 | AK40: 0.76 | AL40: 0 | AM40: 0 | AN40: 类别典型值/文件信息
A41: TZ425 | B41: DBE溶剂 | C41: 聚酯 | D41: 溶剂 | E41: 其他 | F41: COC(=O)CCCC(=O)OC | G41: 已计算 | H41: 0 | I41: 1.09 | J41: 160 | K41: 0 | L41: 0 | M41: 0 | N41: 0 | O41: 0 | P41: -60 | Q41: 210 | R41: 100 | S41: 16.5 | T41: 6.5 | U41: 7.5 | V41: 3 | W41: 0.02 | X41: 50 | Y41: 7 | Z41: 43 | AA41: 0 | AB41: 0 | AC41: 0 | AD41: 0 | AE41: 0 | AF41: 0 | AG41: 0.62 | AH41: 0 | AI41: 0 | AJ41: 0 | AK41: 0.62 | AL41: 0 | AM41: 0 | AN41: 类别典型值/文件信息
A42: TZ240 | B42: 醋酸丁酯 | C42: 有机 | D42: 溶剂 | E42: 其他 | F42: CCCCOC(=O)C | G42: 已计算 | H42: 0 | I42: 0.88 | J42: 116.2 | K42: 0 | L42: 0 | M42: 0 | N42: 0 | O42: 0 | P42: -78 | Q42: 126 | R42: 22 | S42: 15.8 | T42: 3.7 | U42: 6.3 | V42: 2.8 | W42: 1 | X42: 62 | Y42: 10 | Z42: 28 | AA42: 0 | AB42: 0 | AC42: 0 | AD42: 0 | AE42: 0 | AF42: 0 | AG42: 0.86 | AH42: 0 | AI42: 0 | AJ42: 0 | AK42: 0.86 | AL42: 0 | AM42: 0 | AN42: 类别典型值/文件信息
A43: TT444 | B43: 丁酮 | C43: 有机 | D43: 溶剂 | E43: 其他 | F43: CCC(=O)C | G43: 已计算 | H43: 0 | I43: 0.8 | J43: 72.1 | K43: 0 | L43: 0 | M43: 0 | N43: 0 | O43: 0 | P43: -86 | Q43: 79.6 | R43: -9 | S43: 16 | T43: 9 | U43: 5.1 | V43: 4.7 | W43: 3.8 | X43: 67 | Y43: 11 | Z43: 22 | AA43: 0 | AB43: 0 | AC43: 0 | AD43: 0 | AE43: 0 | AF43: 0 | AG43: 0 | AH43: 0 | AI43: 0 | AJ43: 0 | AK43: 0 | AL43: 0 | AM43: 0 | AN43: 类别典型值/文件信息
A44: TT066 | B44: 环己酮 | C44: 有机 | D44: 溶剂 | E44: 其他 | F44: O=C1CCCCC1 | G44: 已计算 | H44: 0 | I44: 0.95 | J44: 98.1 | K44: 0 | L44: 0 | M44: 0 | N44: 0 | O44: 0 | P44: -32 | Q44: 155.6 | R44: 44 | S44: 17.8 | T44: 6.3 | U44: 5.1 | V44: 4.2 | W44: 0.3 | X44: 73 | Y44: 10 | Z44: 16 | AA44: 0 | AB44: 0 | AC44: 0 | AD44: 0 | AE44: 0 | AF44: 0 | AG44: 0 | AH44: 0 | AI44: 0 | AJ44: 0 | AK44: 0 | AL44: 0 | AM44: 0 | AN44: 类别典型值/文件信息
A45: TM982 | B45: PM溶剂 | C45: 有机 | D45: 溶剂 | E45: 其他 | F45: CC(C)OC | G45: 已计算 | H45: 0 | I45: 0.92 | J45: 90.1 | K45: 0 | L45: 0 | M45: 0 | N45: 0 | O45: 0 | P45: -96 | Q45: 120 | R45: 32 | S45: 15.6 | T45: 6.3 | U45: 11.6 | V45: 3.6 | W45: 0.65 | X45: 53 | Y45: 11 | Z45: 36 | AA45: 0 | AB45: 0 | AC45: 0 | AD45: 0 | AE45: 1.11 | AF45: 0 | AG45: 0 | AH45: 0 | AI45: 0 | AJ45: 0 | AK45: 1.11 | AL45: 0 | AM45: 0 | AN45: 类别典型值/文件信息
A46: TM024 | B46: 二乙二醇单丁醚 | C46: 有机 | D46: 溶剂 | E46: 其他 | F46: CCCCOCCOCCO | G46: 已计算 | H46: 0 | I46: 0.96 | J46: 162.2 | K46: 0 | L46: 0 | M46: 0 | N46: 0 | O46: 0 | P46: -68 | Q46: 231 | R46: 100 | S46: 16 | T46: 7 | U46: 10 | V46: 3.4 | W46: 0.01 | X46: 59 | Y46: 11 | Z46: 30 | AA46: 0 | AB46: 0 | AC46: 0 | AD46: 0 | AE46: 0.62 | AF46: 0 | AG46: 0 | AH46: 0 | AI46: 0 | AJ46: 0 | AK46: 0.62 | AL46: 0 | AM46: 0 | AN46: 类别典型值/文件信息
A47: TM221 | B47: 乙二醇丁醚 | C47: 有机 | D47: 溶剂 | E47: 其他 | G47: 专有估算 | H47: 0 | I47: 0.9 | J47: 118.2 | K47: 0 | L47: 0 | M47: 0 | N47: 0 | O47: 0 | P47: -70 | Q47: 171 | R47: 60 | S47: 16 | T47: 5.1 | U47: 12.3 | V47: 3.1 | W47: 0.07 | X47: 61 | Y47: 12 | Z47: 27 | AA47: 0 | AB47: 0 | AC47: 0 | AD47: 0 | AE47: 0.85 | AF47: 0 | AG47: 0 | AH47: 0 | AI47: 0 | AJ47: 0 | AK47: 0.85 | AL47: 0 | AM47: 0 | AN47: 类别典型值/文件信息
A48: TZ221 | B48: 乙二醇丁醚 | C48: 有机 | D48: 溶剂 | E48: 其他 | F48: CCCCOCCO | G48: 已计算 | H48: 0 | I48: 0.9 | J48: 118.2 | K48: 0 | L48: 0 | M48: 0 | N48: 0 | O48: 0 | P48: -70 | Q48: 171 | R48: 60 | S48: 16 | T48: 5.1 | U48: 12.3 | V48: 3.1 | W48: 0.07 | X48: 61 | Y48: 12 | Z48: 27 | AA48: 0 | AB48: 0 | AC48: 0 | AD48: 0 | AE48: 0.85 | AF48: 0 | AG48: 0 | AH48: 0 | AI48: 0 | AJ48: 0 | AK48: 0.85 | AL48: 0 | AM48: 0 | AN48: 类别典型值/文件信息
A49: AZ088 | B49: 分散剂BYK088 | C49: 环氧酚醛 | D49: 助剂 | E49: 其他 | G49: 专有估算 | H49: 5 | I49: 1 | J49: 2000 | K49: 0 | L49: 10 | M49: 30 | N49: 0 | O49: 0 | P49: 20 | Q49: 300 | R49: 150 | S49: 17.5 | T49: 6.5 | U49: 8.5 | V49: 3.2 | W49: 0 | X49: 65 | Y49: 10 | Z49: 20 | AA49: 0 | AB49: 0 | AC49: 0 | AD49: 0 | AE49: 0.018 | AF49: 0.006 | AG49: 0.2 | AH49: 0 | AI49: 0.05 | AJ49: 0.2 | AK49: 0.1 | AL49: 0 | AM49: 0 | AN49: 类别典型值/文件信息
A50: BYK104 | B50: 分散剂BYK104 | C50: 有机 | D50: 助剂 | E50: 其他 | G50: 专有估算 | H50: 100 | I50: 1 | J50: 5000 | K50: 0 | L50: 30 | M50: 20 | N50: 0 | O50: 0 | P50: 20 | Q50: 300 | R50: 150 | S50: 17.5 | T50: 6.5 | U50: 8.5 | V50: 3.2 | W50: 0 | X50: 60 | Y50: 9 | Z50: 30 | AA50: 0 | AB50: 0 | AC50: 0 | AD50: 0 | AE50: 0.012 | AF50: 0.018 | AG50: 0.2 | AH50: 0 | AI50: 0.05 | AJ50: 0.2 | AK50: 0.1 | AL50: 0 | AM50: 0 | AN50: 类别典型值/文件信息
A51: AC040 | B51: 助剂 | C51: 聚酯 | D51: 助剂 | E51: 其他 | G51: 专有估算 | H51: 70 | I51: 1 | J51: 3000 | K51: 0 | L51: 5 | M51: 40 | N51: 0 | O51: 3 | P51: 10 | Q51: 300 | R51: 150 | S51: 17.5 | T51: 6 | U51: 8 | V51: 3 | W51: 0 | X51: 40 | Y51: 7 | Z51: 35 | AA51: 0 | AB51: 0 | AC51: 0 | AD51: 0 | AE51: 0.02 | AF51: 0.003 | AG51: 0.1 | AH51: 0 | AI51: 0.05 | AJ51: 0.2 | AK51: 0.1 | AL51: 0 | AM51: 0 | AN51: 类别典型值/文件信息
A52: AZ135 | B52: 助剂 | C52: 聚酯 | D52: 助剂 | E52: 其他 | G52: 专有估算 | H52: 98 | I52: 1 | J52: 3000 | K52: 0 | L52: 5 | M52: 40 | N52: 0 | O52: 2 | P52: 20 | Q52: 300 | R52: 150 | S52: 17.5 | T52: 6 | U52: 8 | V52: 3 | W52: 0 | X52: 50 | Y52: 8 | Z52: 38 | AA52: 0 | AB52: 0 | AC52: 0 | AD52: 0 | AE52: 0.024 | AF52: 0.003 | AG52: 0.12 | AH52: 0 | AI52: 0.05 | AJ52: 0.2 | AK52: 0.1 | AL52: 0 | AM52: 0 | AN52: 类别典型值/文件信息
A53: AZ306 | B53: 助剂 | C53: 有机 | D53: 助剂 | E53: 其他 | G53: 专有估算 | H53: 12.5 | I53: 1 | J53: 3000 | K53: 0 | L53: 5 | M53: 40 | N53: 0 | O53: 0 | P53: 20 | Q53: 300 | R53: 150 | S53: 17.5 | T53: 6 | U53: 8 | V53: 3 | W53: 0 | X53: 55 | Y53: 9 | Z53: 30 | AA53: 0 | AB53: 0 | AC53: 0 | AD53: 0 | AE53: 0.024 | AF53: 0.003 | AG53: 0.2 | AH53: 0 | AI53: 0.05 | AJ53: 0.2 | AK53: 0.2 | AL53: 0 | AM53: 0 | AN53: 类别典型值/文件信息
A54: AZ551 | B54: 助剂 | C54: 有机 | D54: 助剂 | E54: 其他 | G54: 专有估算 | H54: 100 | I54: 1 | J54: 3000 | K54: 0 | L54: 5 | M54: 40 | N54: 0 | O54: 0 | P54: 20 | Q54: 300 | R54: 150 | S54: 17.5 | T54: 6 | U54: 8 | V54: 3 | W54: 0 | X54: 65 | Y54: 9 | Z54: 25 | AA54: 0 | AB54: 0 | AC54: 0 | AD54: 0 | AE54: 0.024 | AF54: 0.003 | AG54: 0.2 | AH54: 0 | AI54: 0.05 | AJ54: 0.2 | AK54: 0.1 | AL54: 0 | AM54: 0 | AN54: 类别典型值/文件信息
A55: BYK306 | B55: 流平剂 | C55: 有机 | D55: 助剂 | E55: 其他 | G55: 专有估算 | H55: 100 | I55: 1 | J55: 3000 | K55: 0 | L55: 5 | M55: 40 | N55: 0 | O55: 0 | P55: 20 | Q55: 300 | R55: 150 | S55: 17.5 | T55: 6 | U55: 8 | V55: 3 | W55: 0 | X55: 65 | Y55: 9 | Z55: 25 | AA55: 0 | AB55: 0 | AC55: 0 | AD55: 0 | AE55: 0.024 | AF55: 0.003 | AG55: 0.2 | AH55: 0 | AI55: 0.05 | AJ55: 0.2 | AK55: 0.1 | AL55: 0 | AM55: 0 | AN55: 类别典型值/文件信息
A56: FL208 | B56: 助剂 | C56: 有机 | D56: 助剂 | E56: 其他 | G56: 专有估算 | H56: 100 | I56: 1 | J56: 3000 | K56: 0 | L56: 5 | M56: 40 | N56: 0 | O56: 0 | P56: 20 | Q56: 300 | R56: 150 | S56: 17.5 | T56: 6 | U56: 8 | V56: 3 | W56: 0 | X56: 65 | Y56: 9 | Z56: 25 | AA56: 0 | AB56: 0 | AC56: 0 | AD56: 0 | AE56: 0.024 | AF56: 0.003 | AG56: 0.2 | AH56: 0 | AI56: 0.05 | AJ56: 0.2 | AK56: 0.1 | AL56: 0 | AM56: 0 | AN56: 类别典型值/文件信息
A57: FL208S | B57: 助剂 | C57: 有机 | D57: 助剂 | E57: 其他 | G57: 专有估算 | H57: 100 | I57: 1 | J57: 3000 | K57: 0 | L57: 5 | M57: 40 | N57: 0 | O57: 0 | P57: 20 | Q57: 300 | R57: 150 | S57: 17.5 | T57: 6 | U57: 8 | V57: 3 | W57: 0 | X57: 65 | Y57: 9 | Z57: 25 | AA57: 0 | AB57: 0 | AC57: 0 | AD57: 0 | AE57: 0.024 | AF57: 0.003 | AG57: 0.2 | AH57: 0 | AI57: 0.05 | AJ57: 0.2 | AK57: 0.1 | AL57: 0 | AM57: 0 | AN57: 类别典型值/文件信息
A58: FL815C | B58: 助剂 | C58: 有机 | D58: 颜料 | E58: 其他 | G58: 专有估算 | H58: 65 | I58: 1 | J58: 3000 | K58: 0 | L58: 5 | M58: 40 | N58: 0 | O58: 0 | P58: 20 | Q58: 300 | R58: 150 | S58: 17.5 | T58: 6 | U58: 8 | V58: 3 | W58: 0 | X58: 10 | Y58: 0 | Z58: 1 | AA58: 0 | AB58: 0 | AC58: 0 | AD58: 0 | AE58: 0.024 | AF58: 0.003 | AG58: 0.2 | AH58: 0 | AI58: 0.05 | AJ58: 0.2 | AK58: 0.1 | AL58: 0 | AM58: 65 | AN58: 类别典型值/文件信息
A59: RA009 | B59: 助剂 | C59: 有机 | D59: 固化剂 | E59: 氨基 | G59: 专有估算 | H59: 60 | I59: 1 | J59: 3000 | K59: 0 | L59: 5 | M59: 40 | N59: 0 | O59: 5 | P59: 35 | Q59: 300 | R59: 150 | S59: 17.5 | T59: 6 | U59: 8 | V59: 3 | W59: 0 | X59: 60 | Y59: 10 | Z59: 22 | AA59: 22 | AB59: 0 | AC59: 0 | AD59: 0 | AE59: 0.05 | AF59: 0.003 | AG59: 0.05 | AH59: 0.16 | AI59: 0.05 | AJ59: 0.05 | AK59: 0.1 | AL59: 0 | AM59: 0 | AN59: 类别典型值/文件信息
A60: RA083 | B60: 助剂 | C60: 有机 | D60: 固化剂 | E60: 氨基 | G60: 专有估算 | H60: 99.5 | I60: 1 | J60: 3000 | K60: 0 | L60: 5 | M60: 40 | N60: 0 | O60: 5 | P60: 40 | Q60: 300 | R60: 150 | S60: 17.5 | T60: 6 | U60: 8 | V60: 3 | W60: 0 | X60: 58 | Y60: 9 | Z60: 21 | AA60: 25 | AB60: 0 | AC60: 0 | AD60: 0 | AE60: 0.04 | AF60: 0.003 | AG60: 0.05 | AH60: 0.18 | AI60: 0.05 | AJ60: 0.12 | AK60: 0.1 | AL60: 0 | AM60: 0 | AN60: 类别典型值/文件信息
... A62: 1510蜡 | B62: 1510蜡25%工作液 | C62: 环氧酚醛 | D62: 助剂 | E62: 其他 | G62: 专有估算 | H62: 25 | I62: 0.9 | J62: 400 | K62: 0 | L62: 0 | M62: 0 | N62: 0 | O62: 0 | P62: -10 | Q62: 350 | R62: 200 | S62: 16 | T62: 0.5 | U62: 0.5 | V62: 0.5 | W62: 0 | X62: 85 | Y62: 15 | Z62: 0 | AA62: 0 | AB62: 0 | AC62: 0 | AD62: 0 | AE62: 0 | AF62: 0 | AG62: 0 | AH62: 0 | AI62: 0 | AJ62: 0 | AK62: 0 | AL62: 25 | AM62: 0 | AN62: 类别典型值/文件信息
...

Sheet 配方明细
A1: 样本ID | B1: 系列 | C1: 体系 | D1: 原料代码 | E1: 用量(g) | F1: 角色 | G1: 树脂类型 | H1: 固含贡献 | I1: 密度贡献 | J1: 分子量贡献 | K1: EEW贡献 | L1: 酸值贡献 | M1: 羟值贡献 | N1: 胺值贡献 | O1: 官能度贡献 | P1: Tg贡献 | Q1: 沸点贡献 | R1: 闪点贡献 | S1: δD贡献 | T1: δP贡献 | U1: δH贡献 | V1: 极性贡献 | W1: 挥发速率贡献 | X1: C贡献 | Y1: H贡献 | Z1: O贡献 | AA1: N贡献 | AB1: S贡献 | AC1: Cl贡献 | AD1: 环氧基贡献 | AE1: 羟基贡献 | AF1: 羧基贡献 | AG1: 酯基贡献 | AH1: 胺基贡献 | AI1: 酰胺贡献 | AJ1: 芳香环贡献 | AK1: 醚键贡献 | AL1: 蜡贡献 | AM1: 颜料贡献
A2: EP-0001 | B2: EP-A | C2: 环氧酚醛 | D2: IR190 | E2: 66 | F2: =IFERROR(VLOOKUP($D2,'原料主数据'!$A:$E,4,FALSE),"待登记") | G2: =IFERROR(VLOOKUP($D2,'原料主数据'!$A:$E,5,FALSE),"待登记") | H2: =IFERROR($E2*VLOOKUP($D2,'原料主数据'!$A:$AN, 8, FALSE),"") | I2: =IFERROR($E2*VLOOKUP($D2,'原料主数据'!$A:$AN, 9, FALSE),"") | J2: =IFERROR($E2*VLOOKUP($D2,'原料主数据'!$A:$AN, 10, FALSE),"") | K2: =IFERROR($E2*VLOOKUP($D2,'原料主数据'!$A:$AN, 11, FALSE),"") | L2: =IFERROR($E2*VLOOKUP($D2,'原料主数据'!$A:$AN, 12, FALSE),"") | M2: =IFERROR($E2*VLOOKUP($D2,'原料主数据'!$A:$AN, 13, FALSE),"") | N2: =IFERROR($E2*VLOOKUP($D2,'原料主数据'!$A:$AN, 14, FALSE),"") | O2: =IFERROR($E2*VLOOKUP($D2,'原料主数据'!$A:$AN, 15, FALSE),"") | P2: =IFERROR($E2*VLOOKUP($D2,'原料主数据'!$A:$AN, 16, FALSE),"") | Q2: =IFERROR($E2*VLOOKUP($D2,'原料主数据'!$A:$AN, 17, FALSE),"") | R2: =IFERROR($E2*VLOOKUP($D2,'原料主数据'!$A:$AN, 18, FALSE),"") | S2: =IFERROR($E2*VLOOKUP($D2,'原料主数据'!$A:$AN, 19, FALSE),"") | T2: =IFERROR($E2*VLOOKUP($D2,'原料主数据'!$A:$AN, 20, FALSE),"") | U2: =IFERROR($E2*VLOOKUP($D2,'原料主数据'!$A:$AN, 21, FALSE),"") | V2: =IFERROR($E2*VLOOKUP($D2,'原料主数据'!$A:$AN, 22, FALSE),"") | W2: =IFERROR($E2*VLOOKUP($D2,'原料主数据'!$A:$AN, 23, FALSE),"") | X2: =IFERROR($E2*VLOOKUP($D2,'原料主数据'!$A:$AN, 24, FALSE),"") | Y2: =IFERROR($E2*VLOOKUP($D2,'原料主数据'!$A:$AN, 25, FALSE),"") | Z2: =IFERROR($E2*VLOOKUP($D2,'原料主数据'!$A:$AN, 26, FALSE),"") | AA2: =IFERROR($E2*VLOOKUP($D2,'原料主数据'!$A:$AN, 27, FALSE),"") | AB2: =IFERROR($E2*VLOOKUP($D2,'原料主数据'!$A:$AN, 28, FALSE),"") | AC2: =IFERROR($E2*VLOOKUP($D2,'原料主数据'!$A:$AN, 29, FALSE),"") | AD2: =IFERROR($E2*VLOOKUP($D2,'原料主数据'!$A:$AN, 30, FALSE),"") | AE2: =IFERROR($E2*VLOOKUP($D2,'原料主数据'!$A:$AN, 31, FALSE),"") | AF2: =IFERROR($E2*VLOOKUP($D2,'原料主数据'!$A:$AN, 32, FALSE),"") | AG2: =IFERROR($E2*VLOOKUP($D2,'原料主数据'!$A:$AN, 33, FALSE),"") | AH2: =IFERROR($E2*VLOOKUP($D2,'原料主数据'!$A:$AN, 34, FALSE),"") | AI2: =IFERROR($E2*VLOOKUP($D2,'原料主数据'!$A:$AN, 35, FALSE),"") | AJ2: =IFERROR($E2*VLOOKUP($D2,'原料主数据'!$A:$AN, 36, FALSE),"") | AK2: =IFERROR($E2*VLOOKUP($D2,'原料主数据'!$A:$AN, 37, FALSE),"") | AL2: =IFERROR($E2*VLOOKUP($D2,'原料主数据'!$A:$AN, 38, FALSE),"") | AM2: =IFERROR($E2*VLOOKUP($D2,'原料主数据'!$A:$AN, 39, FALSE),"")
A3: EP-0001 | B3: EP-A | C3: 环氧酚醛 | D3: IR809 | E3: 0.12 | F3: =IFERROR(VLOOKUP($D3,'原料主数据'!$A:$E,4,FALSE),"待登记") | G3: =IFERROR(VLOOKUP($D3,'原料主数据'!$A:$E,5,FALSE),"待登记") | H3: =IFERROR($E3*VLOOKUP($D3,'原料主数据'!$A:$AN, 8, FALSE),"") | I3: =IFERROR($E3*VLOOKUP($D3,'原料主数据'!$A:$AN, 9, FALSE),"") | J3: =IFERROR($E3*VLOOKUP($D3,'原料主数据'!$A:$AN, 10, FALSE),"") | K3: =IFERROR($E3*VLOOKUP($D3,'原料主数据'!$A:$AN, 11, FALSE),"") | L3: =IFERROR($E3*VLOOKUP($D3,'原料主数据'!$A:$AN, 12, FALSE),"") | M3: =IFERROR($E3*VLOOKUP($D3,'原料主数据'!$A:$AN, 13, FALSE),"") | N3: =IFERROR($E3*VLOOKUP($D3,'原料主数据'!$A:$AN, 14, FALSE),"") | O3: =IFERROR($E3*VLOOKUP($D3,'原料主数据'!$A:$AN, 15, FALSE),"") | P3: =IFERROR($E3*VLOOKUP($D3,'原料主数据'!$A:$AN, 16, FALSE),"") | Q3: =IFERROR($E3*VLOOKUP($D3,'原料主数据'!$A:$AN, 17, FALSE),"") | R3: =IFERROR($E3*VLOOKUP($D3,'原料主数据'!$A:$AN, 18, FALSE),"") | S3: =IFERROR($E3*VLOOKUP($D3,'原料主数据'!$A:$AN, 19, FALSE),"") | T3: =IFERROR($E3*VLOOKUP($D3,'原料主数据'!$A:$AN, 20, FALSE),"") | U3: =IFERROR($E3*VLOOKUP($D3,'原料主数据'!$A:$AN, 21, FALSE),"") | V3: =IFERROR($E3*VLOOKUP($D3,'原料主数据'!$A:$AN, 22, FALSE),"") | W3: =IFERROR($E3*VLOOKUP($D3,'原料主数据'!$A:$AN, 23, FALSE),"") | X3: =IFERROR($E3*VLOOKUP($D3,'原料主数据'!$A:$AN, 24, FALSE),"") | Y3: =IFERROR($E3*VLOOKUP($D3,'原料主数据'!$A:$AN, 25, FALSE),"") | Z3: =IFERROR($E3*VLOOKUP($D3,'原料主数据'!$A:$AN, 26, FALSE),"") | AA3: =IFERROR($E3*VLOOKUP($D3,'原料主数据'!$A:$AN, 27, FALSE),"") | AB3: =IFERROR($E3*VLOOKUP($D3,'原料主数据'!$A:$AN, 28, FALSE),"") | AC3: =IFERROR($E3*VLOOKUP($D3,'原料主数据'!$A:$AN, 29, FALSE),"") | AD3: =IFERROR($E3*VLOOKUP($D3,'原料主数据'!$A:$AN, 30, FALSE),"") | AE3: =IFERROR($E3*VLOOKUP($D3,'原料主数据'!$A:$AN, 31, FALSE),"") | AF3: =IFERROR($E3*VLOOKUP($D3,'原料主数据'!$A:$AN, 32, FALSE),"") | AG3: =IFERROR($E3*VLOOKUP($D3,'原料主数据'!$A:$AN, 33, FALSE),"") | AH3: =IFERROR($E3*VLOOKUP($D3,'原料主数据'!$A:$AN, 34, FALSE),"") | AI3: =IFERROR($E3*VLOOKUP($D3,'原料主数据'!$A:$AN, 35, FALSE),"") | AJ3: =IFERROR($E3*VLOOKUP($D3,'原料主数据'!$A:$AN, 36, FALSE),"") | AK3: =IFERROR($E3*VLOOKUP($D3,'原料主数据'!$A:$AN, 37, FALSE),"") | AL3: =IFERROR($E3*VLOOKUP($D3,'原料主数据'!$A:$AN, 38, FALSE),"") | AM3: =IFERROR($E3*VLOOKUP($D3,'原料主数据'!$A:$AN, 39, FALSE),"")
A4: EP-0001 | B4: EP-A | C4: 环氧酚醛 | D4: RF516 | E4: 2.64 | F4: =IFERROR(VLOOKUP($D4,'原料主数据'!$A:$E,4,FALSE),"待登记") | G4: =IFERROR(VLOOKUP($D4,'原料主数据'!$A:$E,5,FALSE),"待登记") | H4: =IFERROR($E4*VLOOKUP($D4,'原料主数据'!$A:$AN, 8, FALSE),"") | I4: =IFERROR($E4*VLOOKUP($D4,'原料主数据'!$A:$AN, 9, FALSE),"") | J4: =IFERROR($E4*VLOOKUP($D4,'原料主数据'!$A:$AN, 10, FALSE),"") | K4: =IFERROR($E4*VLOOKUP($D4,'原料主数据'!$A:$AN, 11, FALSE),"") | L4: =IFERROR($E4*VLOOKUP($D4,'原料主数据'!$A:$AN, 12, FALSE),"") | M4: =IFERROR($E4*VLOOKUP($D4,'原料主数据'!$A:$AN, 13, FALSE),"") | N4: =IFERROR($E4*VLOOKUP($D4,'原料主数据'!$A:$AN, 14, FALSE),"") | O4: =IFERROR($E4*VLOOKUP($D4,'原料主数据'!$A:$AN, 15, FALSE),"") | P4: =IFERROR($E4*VLOOKUP($D4,'原料主数据'!$A:$AN, 16, FALSE),"") | Q4: =IFERROR($E4*VLOOKUP($D4,'原料主数据'!$A:$AN, 17, FALSE),"") | R4: =IFERROR($E4*VLOOKUP($D4,'原料主数据'!$A:$AN, 18, FALSE),"") | S4: =IFERROR($E4*VLOOKUP($D4,'原料主数据'!$A:$AN, 19, FALSE),"") | T4: =IFERROR($E4*VLOOKUP($D4,'原料主数据'!$A:$AN, 20, FALSE),"") | U4: =IFERROR($E4*VLOOKUP($D4,'原料主数据'!$A:$AN, 21, FALSE),"") | V4: =IFERROR($E4*VLOOKUP($D4,'原料主数据'!$A:$AN, 22, FALSE),"") | W4: =IFERROR($E4*VLOOKUP($D4,'原料主数据'!$A:$AN, 23, FALSE),"") | X4: =IFERROR($E4*VLOOKUP($D4,'原料主数据'!$A:$AN, 24, FALSE),"") | Y4: =IFERROR($E4*VLOOKUP($D4,'原料主数据'!$A:$AN, 25, FALSE),"") | Z4: =IFERROR($E4*VLOOKUP($D4,'原料主数据'!$A:$AN, 26, FALSE),"") | AA4: =IFERROR($E4*VLOOKUP($D4,'原料主数据'!$A:$AN, 27, FALSE),"") | AB4: =IFERROR($E4*VLOOKUP($D4,'原料主数据'!$A:$AN, 28, FALSE),"") | AC4: =IFERROR($E4*VLOOKUP($D4,'原料主数据'!$A:$AN, 29, FALSE),"") | AD4: =IFERROR($E4*VLOOKUP($D4,'原料主数据'!$A:$AN, 30, FALSE),"") | AE4: =IFERROR($E4*VLOOKUP($D4,'原料主数据'!$A:$AN, 31, FALSE),"") | AF4: =IFERROR($E4*VLOOKUP($D4,'原料主数据'!$A:$AN, 32, FALSE),"") | AG4: =IFERROR($E4*VLOOKUP($D4,'原料主数据'!$A:$AN, 33, FALSE),"") | AH4: =IFERROR($E4*VLOOKUP($D4,'原料主数据'!$A:$AN, 34, FALSE),"") | AI4: =IFERROR($E4*VLOOKUP($D4,'原料主数据'!$A:$AN, 35, FALSE),"") | AJ4: =IFERROR($E4*VLOOKUP($D4,'原料主数据'!$A:$AN, 36, FALSE),"") | AK4: =IFERROR($E4*VLOOKUP($D4,'原料主数据'!$A:$AN, 37, FALSE),"") | AL4: =IFERROR($E4*VLOOKUP($D4,'原料主数据'!$A:$AN, 38, FALSE),"") | AM4: =IFERROR($E4*VLOOKUP($D4,'原料主数据'!$A:$AN, 39, FALSE),"")
A5: EP-0001 | B5: EP-A | C5: 环氧酚醛 | D5: RF956 | E5: 1.53 | F5: =IFERROR(VLOOKUP($D5,'原料主数据'!$A:$E,4,FALSE),"待登记") | G5: =IFERROR(VLOOKUP($D5,'原料主数据'!$A:$E,5,FALSE),"待登记") | H5: =IFERROR($E5*VLOOKUP($D5,'原料主数据'!$A:$AN, 8, FALSE),"") | I5: =IFERROR($E5*VLOOKUP($D5,'原料主数据'!$A:$AN, 9, FALSE),"") | J5: =IFERROR($E5*VLOOKUP($D5,'原料主数据'!$A:$AN, 10, FALSE),"") | K5: =IFERROR($E5*VLOOKUP($D5,'原料主数据'!$A:$AN, 11, FALSE),"") | L5: =IFERROR($E5*VLOOKUP($D5,'原料主数据'!$A:$AN, 12, FALSE),"") | M5: =IFERROR($E5*VLOOKUP($D5,'原料主数据'!$A:$AN, 13, FALSE),"") | N5: =IFERROR($E5*VLOOKUP($D5,'原料主数据'!$A:$AN, 14, FALSE),"") | O5: =IFERROR($E5*VLOOKUP($D5,'原料主数据'!$A:$AN, 15, FALSE),"") | P5: =IFERROR($E5*VLOOKUP($D5,'原料主数据'!$A:$AN, 16, FALSE),"") | Q5: =IFERROR($E5*VLOOKUP($D5,'原料主数据'!$A:$AN, 17, FALSE),"") | R5: =IFERROR($E5*VLOOKUP($D5,'原料主数据'!$A:$AN, 18, FALSE),"") | S5: =IFERROR($E5*VLOOKUP($D5,'原料主数据'!$A:$AN, 19, FALSE),"") | T5: =IFERROR($E5*VLOOKUP($D5,'原料主数据'!$A:$AN, 20, FALSE),"") | U5: =IFERROR($E5*VLOOKUP($D5,'原料主数据'!$A:$AN, 21, FALSE),"") | V5: =IFERROR($E5*VLOOKUP($D5,'原料主数据'!$A:$AN, 22, FALSE),"") | W5: =IFERROR($E5*VLOOKUP($D5,'原料主数据'!$A:$AN, 23, FALSE),"") | X5: =IFERROR($E5*VLOOKUP($D5,'原料主数据'!$A:$AN, 24, FALSE),"") | Y5: =IFERROR($E5*VLOOKUP($D5,'原料主数据'!$A:$AN, 25, FALSE),"") | Z5: =IFERROR($E5*VLOOKUP($D5,'原料主数据'!$A:$AN, 26, FALSE),"") | AA5: =IFERROR($E5*VLOOKUP($D5,'原料主数据'!$A:$AN, 27, FALSE),"") | AB5: =IFERROR($E5*VLOOKUP($D5,'原料主数据'!$A:$AN, 28, FALSE),"") | AC5: =IFERROR($E5*VLOOKUP($D5,'原料主数据'!$A:$AN, 29, FALSE),"") | AD5: =IFERROR($E5*VLOOKUP($D5,'原料主数据'!$A:$AN, 30, FALSE),"") | AE5: =IFERROR($E5*VLOOKUP($D5,'原料主数据'!$A:$AN, 31, FALSE),"") | AF5: =IFERROR($E5*VLOOKUP($D5,'原料主数据'!$A:$AN, 32, FALSE),"") | AG5: =IFERROR($E5*VLOOKUP($D5,'原料主数据'!$A:$AN, 33, FALSE),"") | AH5: =IFERROR($E5*VLOOKUP($D5,'原料主数据'!$A:$AN, 34, FALSE),"") | AI5: =IFERROR($E5*VLOOKUP($D5,'原料主数据'!$A:$AN, 35, FALSE),"") | AJ5: =IFERROR($E5*VLOOKUP($D5,'原料主数据'!$A:$AN, 36, FALSE),"") | AK5: =IFERROR($E5*VLOOKUP($D5,'原料主数据'!$A:$AN, 37, FALSE),"") | AL5: =IFERROR($E5*VLOOKUP($D5,'原料主数据'!$A:$AN, 38, FALSE),"") | AM5: =IFERROR($E5*VLOOKUP($D5,'原料主数据'!$A:$AN, 39, FALSE),"")
A6: EP-0001 | B6: EP-A | C6: 环氧酚醛 | D6: 1510蜡 | E6: 0.79 | F6: =IFERROR(VLOOKUP($D6,'原料主数据'!$A:$E,4,FALSE),"待登记") | G6: =IFERROR(VLOOKUP($D6,'原料主数据'!$A:$E,5,FALSE),"待登记") | H6: =IFERROR($E6*VLOOKUP($D6,'原料主数据'!$A:$AN, 8, FALSE),"") | I6: =IFERROR($E6*VLOOKUP($D6,'原料主数据'!$A:$AN, 9, FALSE),"") | J6: =IFERROR($E6*VLOOKUP($D6,'原料主数据'!$A:$AN, 10, FALSE),"") | K6: =IFERROR($E6*VLOOKUP($D6,'原料主数据'!$A:$AN, 11, FALSE),"") | L6: =IFERROR($E6*VLOOKUP($D6,'原料主数据'!$A:$AN, 12, FALSE),"") | M6: =IFERROR($E6*VLOOKUP($D6,'原料主数据'!$A:$AN, 13, FALSE),"") | N6: =IFERROR($E6*VLOOKUP($D6,'原料主数据'!$A:$AN, 14, FALSE),"") | O6: =IFERROR($E6*VLOOKUP($D6,'原料主数据'!$A:$AN, 15, FALSE),"") | P6: =IFERROR($E6*VLOOKUP($D6,'原料主数据'!$A:$AN, 16, FALSE),"") | Q6: =IFERROR($E6*VLOOKUP($D6,'原料主数据'!$A:$AN, 17, FALSE),"") | R6: =IFERROR($E6*VLOOKUP($D6,'原料主数据'!$A:$AN, 18, FALSE),"") | S6: =IFERROR($E6*VLOOKUP($D6,'原料主数据'!$A:$AN, 19, FALSE),"") | T6: =IFERROR($E6*VLOOKUP($D6,'原料主数据'!$A:$AN, 20, FALSE),"") | U6: =IFERROR($E6*VLOOKUP($D6,'原料主数据'!$A:$AN, 21, FALSE),"") | V6: =IFERROR($E6*VLOOKUP($D6,'原料主数据'!$A:$AN, 22, FALSE),"") | W6: =IFERROR($E6*VLOOKUP($D6,'原料主数据'!$A:$AN, 23, FALSE),"") | X6: =IFERROR($E6*VLOOKUP($D6,'原料主数据'!$A:$AN, 24, FALSE),"") | Y6: =IFERROR($E6*VLOOKUP($D6,'原料主数据'!$A:$AN, 25, FALSE),"") | Z6: =IFERROR($E6*VLOOKUP($D6,'原料主数据'!$A:$AN, 26, FALSE),"") | AA6: =IFERROR($E6*VLOOKUP($D6,'原料主数据'!$A:$AN, 27, FALSE),"") | AB6: =IFERROR($E6*VLOOKUP($D6,'原料主数据'!$A:$AN, 28, FALSE),"") | AC6: =IFERROR($E6*VLOOKUP($D6,'原料主数据'!$A:$AN, 29, FALSE),"") | AD6: =IFERROR($E6*VLOOKUP($D6,'原料主数据'!$A:$AN, 30, FALSE),"") | AE6: =IFERROR($E6*VLOOKUP($D6,'原料主数据'!$A:$AN, 31, FALSE),"") | AF6: =IFERROR($E6*VLOOKUP($D6,'原料主数据'!$A:$AN, 32, FALSE),"") | AG6: =IFERROR($E6*VLOOKUP($D6,'原料主数据'!$A:$AN, 33, FALSE),"") | AH6: =IFERROR($E6*VLOOKUP($D6,'原料主数据'!$A:$AN, 34, FALSE),"") | AI6: =IFERROR($E6*VLOOKUP($D6,'原料主数据'!$A:$AN, 35, FALSE),"") | AJ6: =IFERROR($E6*VLOOKUP($D6,'原料主数据'!$A:$AN, 36, FALSE),"") | AK6: =IFERROR($E6*VLOOKUP($D6,'原料主数据'!$A:$AN, 37, FALSE),"") | AL6: =IFERROR($E6*VLOOKUP($D6,'原料主数据'!$A:$AN, 38, FALSE),"") | AM6: =IFERROR($E6*VLOOKUP($D6,'原料主数据'!$A:$AN, 39, FALSE),"")
A7: EP-0001 | B7: EP-A | C7: 环氧酚醛 | D7: AZ088 | E7: 0.06 | F7: =IFERROR(VLOOKUP($D7,'原料主数据'!$A:$E,4,FALSE),"待登记") | G7: =IFERROR(VLOOKUP($D7,'原料主数据'!$A:$E,5,FALSE),"待登记") | H7: =IFERROR($E7*VLOOKUP($D7,'原料主数据'!$A:$AN, 8, FALSE),"") | I7: =IFERROR($E7*VLOOKUP($D7,'原料主数据'!$A:$AN, 9, FALSE),"") | J7: =IFERROR($E7*VLOOKUP($D7,'原料主数据'!$A:$AN, 10, FALSE),"") | K7: =IFERROR($E7*VLOOKUP($D7,'原料主数据'!$A:$AN, 11, FALSE),"") | L7: =IFERROR($E7*VLOOKUP($D7,'原料主数据'!$A:$AN, 12, FALSE),"") | M7: =IFERROR($E7*VLOOKUP($D7,'原料主数据'!$A:$AN, 13, FALSE),"") | N7: =IFERROR($E7*VLOOKUP($D7,'原料主数据'!$A:$AN, 14, FALSE),"") | O7: =IFERROR($E7*VLOOKUP($D7,'原料主数据'!$A:$AN, 15, FALSE),"") | P7: =IFERROR($E7*VLOOKUP($D7,'原料主数据'!$A:$AN, 16, FALSE),"") | Q7: =IFERROR($E7*VLOOKUP($D7,'原料主数据'!$A:$AN, 17, FALSE),"") | R7: =IFERROR($E7*VLOOKUP($D7,'原料主数据'!$A:$AN, 18, FALSE),"") | S7: =IFERROR($E7*VLOOKUP($D7,'原料主数据'!$A:$AN, 19, FALSE),"") | T7: =IFERROR($E7*VLOOKUP($D7,'原料主数据'!$A:$AN, 20, FALSE),"") | U7: =IFERROR($E7*VLOOKUP($D7,'原料主数据'!$A:$AN, 21, FALSE),"") | V7: =IFERROR($E7*VLOOKUP($D7,'原料主数据'!$A:$AN, 22, FALSE),"") | W7: =IFERROR($E7*VLOOKUP($D7,'原料主数据'!$A:$AN, 23, FALSE),"") | X7: =IFERROR($E7*VLOOKUP($D7,'原料主数据'!$A:$AN, 24, FALSE),"") | Y7: =IFERROR($E7*VLOOKUP($D7,'原料主数据'!$A:$AN, 25, FALSE),"") | Z7: =IFERROR($E7*VLOOKUP($D7,'原料主数据'!$A:$AN, 26, FALSE),"") | AA7: =IFERROR($E7*VLOOKUP($D7,'原料主数据'!$A:$AN, 27, FALSE),"") | AB7: =IFERROR($E7*VLOOKUP($D7,'原料主数据'!$A:$AN, 28, FALSE),"") | AC7: =IFERROR($E7*VLOOKUP($D7,'原料主数据'!$A:$AN, 29, FALSE),"") | AD7: =IFERROR($E7*VLOOKUP($D7,'原料主数据'!$A:$AN, 30, FALSE),"") | AE7: =IFERROR($E7*VLOOKUP($D7,'原料主数据'!$A:$AN, 31, FALSE),"") | AF7: =IFERROR($E7*VLOOKUP($D7,'原料主数据'!$A:$AN, 32, FALSE),"") | AG7: =IFERROR($E7*VLOOKUP($D7,'原料主数据'!$A:$AN, 33, FALSE),"") | AH7: =IFERROR($E7*VLOOKUP($D7,'原料主数据'!$A:$AN, 34, FALSE),"") | AI7: =IFERROR($E7*VLOOKUP($D7,'原料主数据'!$A:$AN, 35, FALSE),"") | AJ7: =IFERROR($E7*VLOOKUP($D7,'原料主数据'!$A:$AN, 36, FALSE),"") | AK7: =IFERROR($E7*VLOOKUP($D7,'原料主数据'!$A:$AN, 37, FALSE),"") | AL7: =IFERROR($E7*VLOOKUP($D7,'原料主数据'!$A:$AN, 38, FALSE),"") | AM7: =IFERROR($E7*VLOOKUP($D7,'原料主数据'!$A:$AN, 39, FALSE),"")
A8: EP-0001 | B8: EP-A | C8: 环氧酚醛 | D8: 正丁醇 | E8: 1.48 | F8: =IFERROR(VLOOKUP($D8,'原料主数据'!$A:$E,4,FALSE),"待登记") | G8: =IFERROR(VLOOKUP($D8,'原料主数据'!$A:$E,5,FALSE),"待登记") | H8: =IFERROR($E8*VLOOKUP($D8,'原料主数据'!$A:$AN, 8, FALSE),"") | I8: =IFERROR($E8*VLOOKUP($D8,'原料主数据'!$A:$AN, 9, FALSE),"") | J8: =IFERROR($E8*VLOOKUP($D8,'原料主数据'!$A:$AN, 10, FALSE),"") | K8: =IFERROR($E8*VLOOKUP($D8,'原料主数据'!$A:$AN, 11, FALSE),"") | L8: =IFERROR($E8*VLOOKUP($D8,'原料主数据'!$A:$AN, 12, FALSE),"") | M8: =IFERROR($E8*VLOOKUP($D8,'原料主数据'!$A:$AN, 13, FALSE),"") | N8: =IFERROR($E8*VLOOKUP($D8,'原料主数据'!$A:$AN, 14, FALSE),"") | O8: =IFERROR($E8*VLOOKUP($D8,'原料主数据'!$A:$AN, 15, FALSE),"") | P8: =IFERROR($E8*VLOOKUP($D8,'原料主数据'!$A:$AN, 16, FALSE),"") | Q8: =IFERROR($E8*VLOOKUP($D8,'原料主数据'!$A:$AN, 17, FALSE),"") | R8: =IFERROR($E8*VLOOKUP($D8,'原料主数据'!$A:$AN, 18, FALSE),"") | S8: =IFERROR($E8*VLOOKUP($D8,'原料主数据'!$A:$AN, 19, FALSE),"") | T8: =IFERROR($E8*VLOOKUP($D8,'原料主数据'!$A:$AN, 20, FALSE),"") | U8: =IFERROR($E8*VLOOKUP($D8,'原料主数据'!$A:$AN, 21, FALSE),"") | V8: =IFERROR($E8*VLOOKUP($D8,'原料主数据'!$A:$AN, 22, FALSE),"") | W8: =IFERROR($E8*VLOOKUP($D8,'原料主数据'!$A:$AN, 23, FALSE),"") | X8: =IFERROR($E8*VLOOKUP($D8,'原料主数据'!$A:$AN, 24, FALSE),"") | Y8: =IFERROR($E8*VLOOKUP($D8,'原料主数据'!$A:$AN, 25, FALSE),"") | Z8: =IFERROR($E8*VLOOKUP($D8,'原料主数据'!$A:$AN, 26, FALSE),"") | AA8: =IFERROR($E8*VLOOKUP($D8,'原料主数据'!$A:$AN, 27, FALSE),"") | AB8: =IFERROR($E8*VLOOKUP($D8,'原料主数据'!$A:$AN, 28, FALSE),"") | AC8: =IFERROR($E8*VLOOKUP($D8,'原料主数据'!$A:$AN, 29, FALSE),"") | AD8: =IFERROR($E8*VLOOKUP($D8,'原料主数据'!$A:$AN, 30, FALSE),"") | AE8: =IFERROR($E8*VLOOKUP($D8,'原料主数据'!$A:$AN, 31, FALSE),"") | AF8: =IFERROR($E8*VLOOKUP($D8,'原料主数据'!$A:$AN, 32, FALSE),"") | AG8: =IFERROR($E8*VLOOKUP($D8,'原料主数据'!$A:$AN, 33, FALSE),"") | AH8: =IFERROR($E8*VLOOKUP($D8,'原料主数据'!$A:$AN, 34, FALSE),"") | AI8: =IFERROR($E8*VLOOKUP($D8,'原料主数据'!$A:$AN, 35, FALSE),"") | AJ8: =IFERROR($E8*VLOOKUP($D8,'原料主数据'!$A:$AN, 36, FALSE),"") | AK8: =IFERROR($E8*VLOOKUP($D8,'原料主数据'!$A:$AN, 37, FALSE),"") | AL8: =IFERROR($E8*VLOOKUP($D8,'原料主数据'!$A:$AN, 38, FALSE),"") | AM8: =IFERROR($E8*VLOOKUP($D8,'原料主数据'!$A:$AN, 39, FALSE),"")
A9: EP-0001 | B9: EP-A | C9: 环氧酚醛 | D9: 补加混合液 | E9: 1.27 | F9: =IFERROR(VLOOKUP($D9,'原料主数据'!$A:$E,4,FALSE),"待登记") | G9: =IFERROR(VLOOKUP($D9,'原料主数据'!$A:$E,5,FALSE),"待登记") | H9: =IFERROR($E9*VLOOKUP($D9,'原料主数据'!$A:$AN, 8, FALSE),"") | I9: =IFERROR($E9*VLOOKUP($D9,'原料主数据'!$A:$AN, 9, FALSE),"") | J9: =IFERROR($E9*VLOOKUP($D9,'原料主数据'!$A:$AN, 10, FALSE),"") | K9: =IFERROR($E9*VLOOKUP($D9,'原料主数据'!$A:$AN, 11, FALSE),"") | L9: =IFERROR($E9*VLOOKUP($D9,'原料主数据'!$A:$AN, 12, FALSE),"") | M9: =IFERROR($E9*VLOOKUP($D9,'原料主数据'!$A:$AN, 13, FALSE),"") | N9: =IFERROR($E9*VLOOKUP($D9,'原料主数据'!$A:$AN, 14, FALSE),"") | O9: =IFERROR($E9*VLOOKUP($D9,'原料主数据'!$A:$AN, 15, FALSE),"") | P9: =IFERROR($E9*VLOOKUP($D9,'原料主数据'!$A:$AN, 16, FALSE),"") | Q9: =IFERROR($E9*VLOOKUP($D9,'原料主数据'!$A:$AN, 17, FALSE),"") | R9: =IFERROR($E9*VLOOKUP($D9,'原料主数据'!$A:$AN, 18, FALSE),"") | S9: =IFERROR($E9*VLOOKUP($D9,'原料主数据'!$A:$AN, 19, FALSE),"") | T9: =IFERROR($E9*VLOOKUP($D9,'原料主数据'!$A:$AN, 20, FALSE),"") | U9: =IFERROR($E9*VLOOKUP($D9,'原料主数据'!$A:$AN, 21, FALSE),"") | V9: =IFERROR($E9*VLOOKUP($D9,'原料主数据'!$A:$AN, 22, FALSE),"") | W9: =IFERROR($E9*VLOOKUP($D9,'原料主数据'!$A:$AN, 23, FALSE),"") | X9: =IFERROR($E9*VLOOKUP($D9,'原料主数据'!$A:$AN, 24, FALSE),"") | Y9: =IFERROR($E9*VLOOKUP($D9,'原料主数据'!$A:$AN, 25, FALSE),"") | Z9: =IFERROR($E9*VLOOKUP($D9,'原料主数据'!$A:$AN, 26, FALSE),"") | AA9: =IFERROR($E9*VLOOKUP($D9,'原料主数据'!$A:$AN, 27, FALSE),"") | AB9: =IFERROR($E9*VLOOKUP($D9,'原料主数据'!$A:$AN, 28, FALSE),"") | AC9: =IFERROR($E9*VLOOKUP($D9,'原料主数据'!$A:$AN, 29, FALSE),"") | AD9: =IFERROR($E9*VLOOKUP($D9,'原料主数据'!$A:$AN, 30, FALSE),"") | AE9: =IFERROR($E9*VLOOKUP($D9,'原料主数据'!$A:$AN, 31, FALSE),"") | AF9: =IFERROR($E9*VLOOKUP($D9,'原料主数据'!$A:$AN, 32, FALSE),"") | AG9: =IFERROR($E9*VLOOKUP($D9,'原料主数据'!$A:$AN, 33, FALSE),"") | AH9: =IFERROR($E9*VLOOKUP($D9,'原料主数据'!$A:$AN, 34, FALSE),"") | AI9: =IFERROR($E9*VLOOKUP($D9,'原料主数据'!$A:$AN, 35, FALSE),"") | AJ9: =IFERROR($E9*VLOOKUP($D9,'原料主数据'!$A:$AN, 36, FALSE),"") | AK9: =IFERROR($E9*VLOOKUP($D9,'原料主数据'!$A:$AN, 37, FALSE),"") | AL9: =IFERROR($E9*VLOOKUP($D9,'原料主数据'!$A:$AN, 38, FALSE),"") | AM9: =IFERROR($E9*VLOOKUP($D9,'原料主数据'!$A:$AN, 39, FALSE),"")
A10: EP-0002 | B10: EP-A | C10: 环氧酚醛 | D10: IR190 | E10: 66.09 | F10: =IFERROR(VLOOKUP($D10,'原料主数据'!$A:$E,4,FALSE),"待登记") | G10: =IFERROR(VLOOKUP($D10,'原料主数据'!$A:$E,5,FALSE),"待登记") | H10: =IFERROR($E10*VLOOKUP($D10,'原料主数据'!$A:$AN, 8, FALSE),"") | I10: =IFERROR($E10*VLOOKUP($D10,'原料主数据'!$A:$AN, 9, FALSE),"") | J10: =IFERROR($E10*VLOOKUP($D10,'原料主数据'!$A:$AN, 10, FALSE),"") | K10: =IFERROR($E10*VLOOKUP($D10,'原料主数据'!$A:$AN, 11, FALSE),"") | L10: =IFERROR($E10*VLOOKUP($D10,'原料主数据'!$A:$AN, 12, FALSE),"") | M10: =IFERROR($E10*VLOOKUP($D10,'原料主数据'!$A:$AN, 13, FALSE),"") | N10: =IFERROR($E10*VLOOKUP($D10,'原料主数据'!$A:$AN, 14, FALSE),"") | O10: =IFERROR($E10*VLOOKUP($D10,'原料主数据'!$A:$AN, 15, FALSE),"") | P10: =IFERROR($E10*VLOOKUP($D10,'原料主数据'!$A:$AN, 16, FALSE),"") | Q10: =IFERROR($E10*VLOOKUP($D10,'原料主数据'!$A:$AN, 17, FALSE),"") | R10: =IFERROR($E10*VLOOKUP($D10,'原料主数据'!$A:$AN, 18, FALSE),"") | S10: =IFERROR($E10*VLOOKUP($D10,'原料主数据'!$A:$AN, 19, FALSE),"") | T10: =IFERROR($E10*VLOOKUP($D10,'原料主数据'!$A:$AN, 20, FALSE),"") | U10: =IFERROR($E10*VLOOKUP($D10,'原料主数据'!$A:$AN, 21, FALSE),"") | V10: =IFERROR($E10*VLOOKUP($D10,'原料主数据'!$A:$AN, 22, FALSE),"") | W10: =IFERROR($E10*VLOOKUP($D10,'原料主数据'!$A:$AN, 23, FALSE),"") | X10: =IFERROR($E10*VLOOKUP($D10,'原料主数据'!$A:$AN, 24, FALSE),"") | Y10: =IFERROR($E10*VLOOKUP($D10,'原料主数据'!$A:$AN, 25, FALSE),"") | Z10: =IFERROR($E10*VLOOKUP($D10,'原料主数据'!$A:$AN, 26, FALSE),"") | AA10: =IFERROR($E10*VLOOKUP($D10,'原料主数据'!$A:$AN, 27, FALSE),"") | AB10: =IFERROR($E10*VLOOKUP($D10,'原料主数据'!$A:$AN, 28, FALSE),"") | AC10: =IFERROR($E10*VLOOKUP($D10,'原料主数据'!$A:$AN, 29, FALSE),"") | AD10: =IFERROR($E10*VLOOKUP($D10,'原料主数据'!$A:$AN, 30, FALSE),"") | AE10: =IFERROR($E10*VLOOKUP($D10,'原料主数据'!$A:$AN, 31, FALSE),"") | AF10: =IFERROR($E10*VLOOKUP($D10,'原料主数据'!$A:$AN, 32, FALSE),"") | AG10: =IFERROR($E10*VLOOKUP($D10,'原料主数据'!$A:$AN, 33, FALSE),"") | AH10: =IFERROR($E10*VLOOKUP($D10,'原料主数据'!$A:$AN, 34, FALSE),"") | AI10: =IFERROR($E10*VLOOKUP($D10,'原料主数据'!$A:$AN, 35, FALSE),"") | AJ10: =IFERROR($E10*VLOOKUP($D10,'原料主数据'!$A:$AN, 36, FALSE),"") | AK10: =IFERROR($E10*VLOOKUP($D10,'原料主数据'!$A:$AN, 37, FALSE),"") | AL10: =IFERROR($E10*VLOOKUP($D10,'原料主数据'!$A:$AN, 38, FALSE),"") | AM10: =IFERROR($E10*VLOOKUP($D10,'原料主数据'!$A:$AN, 39, FALSE),"")
A11: EP-0002 | B11: EP-A | C11: 环氧酚醛 | D11: RF401 | E11: 0.96 | F11: =IFERROR(VLOOKUP($D11,'原料主数据'!$A:$E,4,FALSE),"待登记") | G11: =IFERROR(VLOOKUP($D11,'原料主数据'!$A:$E,5,FALSE),"待登记") | H11: =IFERROR($E11*VLOOKUP($D11,'原料主数据'!$A:$AN, 8, FALSE),"") | I11: =IFERROR($E11*VLOOKUP($D11,'原料主数据'!$A:$AN, 9, FALSE),"") | J11: =IFERROR($E11*VLOOKUP($D11,'原料主数据'!$A:$AN, 10, FALSE),"") | K11: =IFERROR($E11*VLOOKUP($D11,'原料主数据'!$A:$AN, 11, FALSE),"") | L11: =IFERROR($E11*VLOOKUP($D11,'原料主数据'!$A:$AN, 12, FALSE),"") | M11: =IFERROR($E11*VLOOKUP($D11,'原料主数据'!$A:$AN, 13, FALSE),"") | N11: =IFERROR($E11*VLOOKUP($D11,'原料主数据'!$A:$AN, 14, FALSE),"") | O11: =IFERROR($E11*VLOOKUP($D11,'原料主数据'!$A:$AN, 15, FALSE),"") | P11: =IFERROR($E11*VLOOKUP($D11,'原料主数据'!$A:$AN, 16, FALSE),"") | Q11: =IFERROR($E11*VLOOKUP($D11,'原料主数据'!$A:$AN, 17, FALSE),"") | R11: =IFERROR($E11*VLOOKUP($D11,'原料主数据'!$A:$AN, 18, FALSE),"") | S11: =IFERROR($E11*VLOOKUP($D11,'原料主数据'!$A:$AN, 19, FALSE),"") | T11: =IFERROR($E11*VLOOKUP($D11,'原料主数据'!$A:$AN, 20, FALSE),"") | U11: =IFERROR($E11*VLOOKUP($D11,'原料主数据'!$A:$AN, 21, FALSE),"") | V11: =IFERROR($E11*VLOOKUP($D11,'原料主数据'!$A:$AN, 22, FALSE),"") | W11: =IFERROR($E11*VLOOKUP($D11,'原料主数据'!$A:$AN, 23, FALSE),"") | X11: =IFERROR($E11*VLOOKUP($D11,'原料主数据'!$A:$AN, 24, FALSE),"") | Y11: =IFERROR($E11*VLOOKUP($D11,'原料主数据'!$A:$AN, 25, FALSE),"") | Z11: =IFERROR($E11*VLOOKUP($D11,'原料主数据'!$A:$AN, 26, FALSE),"") | AA11: =IFERROR($E11*VLOOKUP($D11,'原料主数据'!$A:$AN, 27, FALSE),"") | AB11: =IFERROR($E11*VLOOKUP($D11,'原料主数据'!$A:$AN, 28, FALSE),"") | AC11: =IFERROR($E11*VLOOKUP($D11,'原料主数据'!$A:$AN, 29, FALSE),"") | AD11: =IFERROR($E11*VLOOKUP($D11,'原料主数据'!$A:$AN, 30, FALSE),"") | AE11: =IFERROR($E11*VLOOKUP($D11,'原料主数据'!$A:$AN, 31, FALSE),"") | AF11: =IFERROR($E11*VLOOKUP($D11,'原料主数据'!$A:$AN, 32, FALSE),"") | AG11: =IFERROR($E11*VLOOKUP($D11,'原料主数据'!$A:$AN, 33, FALSE),"") | AH11: =IFERROR($E11*VLOOKUP($D11,'原料主数据'!$A:$AN, 34, FALSE),"") | AI11: =IFERROR($E11*VLOOKUP($D11,'原料主数据'!$A:$AN, 35, FALSE),"") | AJ11: =IFERROR($E11*VLOOKUP($D11,'原料主数据'!$A:$AN, 36, FALSE),"") | AK11: =IFERROR($E11*VLOOKUP($D11,'原料主数据'!$A:$AN, 37, FALSE),"") | AL11: =IFERROR($E11*VLOOKUP($D11,'原料主数据'!$A:$AN, 38, FALSE),"") | AM11: =IFERROR($E11*VLOOKUP($D11,'原料主数据'!$A:$AN, 39, FALSE),"")
A12: EP-0002 | B12: EP-A | C12: 环氧酚醛 | D12: RF516 | E12: 0.48 | F12: =IFERROR(VLOOKUP($D12,'原料主数据'!$A:$E,4,FALSE),"待登记") | G12: =IFERROR(VLOOKUP($D12,'原料主数据'!$A:$E,5,FALSE),"待登记") | H12: =IFERROR($E12*VLOOKUP($D12,'原料主数据'!$A:$AN, 8, FALSE),"") | I12: =IFERROR($E12*VLOOKUP($D12,'原料主数据'!$A:$AN, 9, FALSE),"") | J12: =IFERROR($E12*VLOOKUP($D12,'原料主数据'!$A:$AN, 10, FALSE),"") | K12: =IFERROR($E12*VLOOKUP($D12,'原料主数据'!$A:$AN, 11, FALSE),"") | L12: =IFERROR($E12*VLOOKUP($D12,'原料主数据'!$A:$AN, 12, FALSE),"") | M12: =IFERROR($E12*VLOOKUP($D12,'原料主数据'!$A:$AN, 13, FALSE),"") | N12: =IFERROR($E12*VLOOKUP($D12,'原料主数据'!$A:$AN, 14, FALSE),"") | O12: =IFERROR($E12*VLOOKUP($D12,'原料主数据'!$A:$AN, 15, FALSE),"") | P12: =IFERROR($E12*VLOOKUP($D12,'原料主数据'!$A:$AN, 16, FALSE),"") | Q12: =IFERROR($E12*VLOOKUP($D12,'原料主数据'!$A:$AN, 17, FALSE),"") | R12: =IFERROR($E12*VLOOKUP($D12,'原料主数据'!$A:$AN, 18, FALSE),"") | S12: =IFERROR($E12*VLOOKUP($D12,'原料主数据'!$A:$AN, 19, FALSE),"") | T12: =IFERROR($E12*VLOOKUP($D12,'原料主数据'!$A:$AN, 20, FALSE),"") | U12: =IFERROR($E12*VLOOKUP($D12,'原料主数据'!$A:$AN, 21, FALSE),"") | V12: =IFERROR($E12*VLOOKUP($D12,'原料主数据'!$A:$AN, 22, FALSE),"") | W12: =IFERROR($E12*VLOOKUP($D12,'原料主数据'!$A:$AN, 23, FALSE),"") | X12: =IFERROR($E12*VLOOKUP($D12,'原料主数据'!$A:$AN, 24, FALSE),"") | Y12: =IFERROR($E12*VLOOKUP($D12,'原料主数据'!$A:$AN, 25, FALSE),"") | Z12: =IFERROR($E12*VLOOKUP($D12,'原料主数据'!$A:$AN, 26, FALSE),"") | AA12: =IFERROR($E12*VLOOKUP($D12,'原料主数据'!$A:$AN, 27, FALSE),"") | AB12: =IFERROR($E12*VLOOKUP($D12,'原料主数据'!$A:$AN, 28, FALSE),"") | AC12: =IFERROR($E12*VLOOKUP($D12,'原料主数据'!$A:$AN, 29, FALSE),"") | AD12: =IFERROR($E12*VLOOKUP($D12,'原料主数据'!$A:$AN, 30, FALSE),"") | AE12: =IFERROR($E12*VLOOKUP($D12,'原料主数据'!$A:$AN, 31, FALSE),"") | AF12: =IFERROR($E12*VLOOKUP($D12,'原料主数据'!$A:$AN, 32, FALSE),"") | AG12: =IFERROR($E12*VLOOKUP($D12,'原料主数据'!$A:$AN, 33, FALSE),"") | AH12: =IFERROR($E12*VLOOKUP($D12,'原料主数据'!$A:$AN, 34, FALSE),"") | AI12: =IFERROR($E12*VLOOKUP($D12,'原料主数据'!$A:$AN, 35, FALSE),"") | AJ12: =IFERROR($E12*VLOOKUP($D12,'原料主数据'!$A:$AN, 36, FALSE),"") | AK12: =IFERROR($E12*VLOOKUP($D12,'原料主数据'!$A:$AN, 37, FALSE),"") | AL12: =IFERROR($E12*VLOOKUP($D12,'原料主数据'!$A:$AN, 38, FALSE),"") | AM12: =IFERROR($E12*VLOOKUP($D12,'原料主数据'!$A:$AN, 39, FALSE),"")
A13: EP-0002 | B13: EP-A | C13: 环氧酚醛 | D13: RF950 | E13: 6.29 | F13: =IFERROR(VLOOKUP($D13,'原料主数据'!$A:$E,4,FALSE),"待登记") | G13: =IFERROR(VLOOKUP($D13,'原料主数据'!$A:$E,5,FALSE),"待登记") | H13: =IFERROR($E13*VLOOKUP($D13,'原料主数据'!$A:$AN, 8, FALSE),"") | I13: =IFERROR($E13*VLOOKUP($D13,'原料主数据'!$A:$AN, 9, FALSE),"") | J13: =IFERROR($E13*VLOOKUP($D13,'原料主数据'!$A:$AN, 10, FALSE),"") | K13: =IFERROR($E13*VLOOKUP($D13,'原料主数据'!$A:$AN, 11, FALSE),"") | L13: =IFERROR($E13*VLOOKUP($D13,'原料主数据'!$A:$AN, 12, FALSE),"") | M13: =IFERROR($E13*VLOOKUP($D13,'原料主数据'!$A:$AN, 13, FALSE),"") | N13: =IFERROR($E13*VLOOKUP($D13,'原料主数据'!$A:$AN, 14, FALSE),"") | O13: =IFERROR($E13*VLOOKUP($D13,'原料主数据'!$A:$AN, 15, FALSE),"") | P13: =IFERROR($E13*VLOOKUP($D13,'原料主数据'!$A:$AN, 16, FALSE),"") | Q13: =IFERROR($E13*VLOOKUP($D13,'原料主数据'!$A:$AN, 17, FALSE),"") | R13: =IFERROR($E13*VLOOKUP($D13,'原料主数据'!$A:$AN, 18, FALSE),"") | S13: =IFERROR($E13*VLOOKUP($D13,'原料主数据'!$A:$AN, 19, FALSE),"") | T13: =IFERROR($E13*VLOOKUP($D13,'原料主数据'!$A:$AN, 20, FALSE),"") | U13: =IFERROR($E13*VLOOKUP($D13,'原料主数据'!$A:$AN, 21, FALSE),"") | V13: =IFERROR($E13*VLOOKUP($D13,'原料主数据'!$A:$AN, 22, FALSE),"") | W13: =IFERROR($E13*VLOOKUP($D13,'原料主数据'!$A:$AN, 23, FALSE),"") | X13: =IFERROR($E13*VLOOKUP($D13,'原料主数据'!$A:$AN, 24, FALSE),"") | Y13: =IFERROR($E13*VLOOKUP($D13,'原料主数据'!$A:$AN, 25, FALSE),"") | Z13: =IFERROR($E13*VLOOKUP($D13,'原料主数据'!$A:$AN, 26, FALSE),"") | AA13: =IFERROR($E13*VLOOKUP($D13,'原料主数据'!$A:$AN, 27, FALSE),"") | AB13: =IFERROR($E13*VLOOKUP($D13,'原料主数据'!$A:$AN, 28, FALSE),"") | AC13: =IFERROR($E13*VLOOKUP($D13,'原料主数据'!$A:$AN, 29, FALSE),"") | AD13: =IFERROR($E13*VLOOKUP($D13,'原料主数据'!$A:$AN, 30, FALSE),"") | AE13: =IFERROR($E13*VLOOKUP($D13,'原料主数据'!$A:$AN, 31, FALSE),"") | AF13: =IFERROR($E13*VLOOKUP($D13,'原料主数据'!$A:$AN, 32, FALSE),"") | AG13: =IFERROR($E13*VLOOKUP($D13,'原料主数据'!$A:$AN, 33, FALSE),"") | AH13: =IFERROR($E13*VLOOKUP($D13,'原料主数据'!$A:$AN, 34, FALSE),"") | AI13: =IFERROR($E13*VLOOKUP($D13,'原料主数据'!$A:$AN, 35, FALSE),"") | AJ13: =IFERROR($E13*VLOOKUP($D13,'原料主数据'!$A:$AN, 36, FALSE),"") | AK13: =IFERROR($E13*VLOOKUP($D13,'原料主数据'!$A:$AN, 37, FALSE),"") | AL13: =IFERROR($E13*VLOOKUP($D13,'原料主数据'!$A:$AN, 38, FALSE),"") | AM13: =IFERROR($E13*VLOOKUP($D13,'原料主数据'!$A:$AN, 39, FALSE),"")
... A93: PES-0003 | B93: PES-B | C93: 聚酯 | D93: TM004 | E93: 1.35 | F93: =IFERROR(VLOOKUP($D93,'原料主数据'!$A:$E,4,FALSE),"待登记") | G93: =IFERROR(VLOOKUP($D93,'原料主数据'!$A:$E,5,FALSE),"待登记") | H93: =IFERROR($E93*VLOOKUP($D93,'原料主数据'!$A:$AN, 8, FALSE),"") | I93: =IFERROR($E93*VLOOKUP($D93,'原料主数据'!$A:$AN, 9, FALSE),"") | J93: =IFERROR($E93*VLOOKUP($D93,'原料主数据'!$A:$AN, 10, FALSE),"") | K93: =IFERROR($E93*VLOOKUP($D93,'原料主数据'!$A:$AN, 11, FALSE),"") | L93: =IFERROR($E93*VLOOKUP($D93,'原料主数据'!$A:$AN, 12, FALSE),"") | M93: =IFERROR($E93*VLOOKUP($D93,'原料主数据'!$A:$AN, 13, FALSE),"") | N93: =IFERROR($E93*VLOOKUP($D93,'原料主数据'!$A:$AN, 14, FALSE),"") | O93: =IFERROR($E93*VLOOKUP($D93,'原料主数据'!$A:$AN, 15, FALSE),"") | P93: =IFERROR($E93*VLOOKUP($D93,'原料主数据'!$A:$AN, 16, FALSE),"") | Q93: =IFERROR($E93*VLOOKUP($D93,'原料主数据'!$A:$AN, 17, FALSE),"") | R93: =IFERROR($E93*VLOOKUP($D93,'原料主数据'!$A:$AN, 18, FALSE),"") | S93: =IFERROR($E93*VLOOKUP($D93,'原料主数据'!$A:$AN, 19, FALSE),"") | T93: =IFERROR($E93*VLOOKUP($D93,'原料主数据'!$A:$AN, 20, FALSE),"") | U93: =IFERROR($E93*VLOOKUP($D93,'原料主数据'!$A:$AN, 21, FALSE),"") | V93: =IFERROR($E93*VLOOKUP($D93,'原料主数据'!$A:$AN, 22, FALSE),"") | W93: =IFERROR($E93*VLOOKUP($D93,'原料主数据'!$A:$AN, 23, FALSE),"") | X93: =IFERROR($E93*VLOOKUP($D93,'原料主数据'!$A:$AN, 24, FALSE),"") | Y93: =IFERROR($E93*VLOOKUP($D93,'原料主数据'!$A:$AN, 25, FALSE),"") | Z93: =IFERROR($E93*VLOOKUP($D93,'原料主数据'!$A:$AN, 26, FALSE),"") | AA93: =IFERROR($E93*VLOOKUP($D93,'原料主数据'!$A:$AN, 27, FALSE),"") | AB93: =IFERROR($E93*VLOOKUP($D93,'原料主数据'!$A:$AN, 28, FALSE),"") | AC93: =IFERROR($E93*VLOOKUP($D93,'原料主数据'!$A:$AN, 29, FALSE),"") | AD93: =IFERROR($E93*VLOOKUP($D93,'原料主数据'!$A:$AN, 30, FALSE),"") | AE93: =IFERROR($E93*VLOOKUP($D93,'原料主数据'!$A:$AN, 31, FALSE),"") | AF93: =IFERROR($E93*VLOOKUP($D93,'原料主数据'!$A:$AN, 32, FALSE),"") | AG93: =IFERROR($E93*VLOOKUP($D93,'原料主数据'!$A:$AN, 33, FALSE),"") | AH93: =IFERROR($E93*VLOOKUP($D93,'原料主数据'!$A:$AN, 34, FALSE),"") | AI93: =IFERROR($E93*VLOOKUP($D93,'原料主数据'!$A:$AN, 35, FALSE),"") | AJ93: =IFERROR($E93*VLOOKUP($D93,'原料主数据'!$A:$AN, 36, FALSE),"") | AK93: =IFERROR($E93*VLOOKUP($D93,'原料主数据'!$A:$AN, 37, FALSE),"") | AL93: =IFERROR($E93*VLOOKUP($D93,'原料主数据'!$A:$AN, 38, FALSE),"") | AM93: =IFERROR($E93*VLOOKUP($D93,'原料主数据'!$A:$AN, 39, FALSE),"")

Sheet 性能结果
A1: 样本ID | B1: 体系 | C1: 目标属性 | D1: 测试值 | E1: 单位 | F1: 标签状态 | G1: 标签来源 | H1: 不确定性 | I1: 测试条件 | J1: 测试日期 | K1: 备注
A2: EP-0001 | B2: 环氧酚醛 | C2: T弯 | D2: 17.415 | E2: mm | F2: 实测 | G2: 实验室 | I2: 205℃ 17min | J2: 2026-08-06
A3: EP-0001 | B3: 环氧酚醛 | C3: MEK擦拭 | D3: 9 | E3: 次 | F3: 实测 | G3: 实验室 | I3: 205℃ 17min | J3: 2026-08-06
A4: EP-0001 | B4: 环氧酚醛 | C4: 水煮等级 | D4: 4 | E4: 级 | F4: 实测 | G4: 实验室 | I4: 205℃ 17min | J4: 2026-08-06
A5: EP-0002 | B5: 环氧酚醛 | C5: T弯 | D5: 19.22 | E5: mm | F5: 实测 | G5: 实验室 | I5: 205℃ 17min | J5: 2026-08-06
A6: EP-0002 | B6: 环氧酚醛 | C6: MEK擦拭 | D6: 161 | E6: 次 | F6: 实测 | G6: 实验室 | I6: 205℃ 17min | J6: 2026-08-06
A7: EP-0003 | B7: 环氧酚醛 | C7: T弯 | D7: 18.05 | E7: mm | F7: 实测 | G7: 实验室 | I7: 205℃ 17min | J7: 2026-08-06
A8: EP-0004 | B8: 环氧酚醛 | C8: T弯 | D8: 20.8 | E8: mm | F8: 实测 | G8: 实验室 | I8: 205℃ 17min | J8: 2026-08-06
A9: EP-0004 | B9: 环氧酚醛 | C9: MEK擦拭 | D9: 300 | E9: 次 | F9: 实测 | G9: 实验室 | I9: 205℃ 17min | J9: 2026-08-06 | K9: 超量程按300计
A10: ORG-0001 | B10: 有机 | C10: T弯 | E10: mm | F10: 推荐测试 | G10: 主动学习 | H10: 0.42 | I10: 双涂双烘190+205℃*12min | J10: 2026-08-06
A11: ORG-0002 | B11: 有机 | C11: T弯 | E11: mm | F11: 伪标签 | G11: 模型预测 | H11: 0.31 | I11: 双涂双烘190+205℃*12min | J11: 2026-08-06
A12: PES-0001 | B12: 聚酯 | C12: T弯 | E12: mm | F12: 人工复核 | G12: 模型预测 | H12: 0.68 | I12: 待定 | J12: 2026-08-06

Sheet 工艺条件
A1: 样本ID | B1: 体系 | C1: 烘烤温度(℃) | D1: 烘烤时间(min) | E1: 膜厚(g/m²) | F1: 基材 | G1: 批次 | H1: 线棒号 | I1: 备注
A2: EP-0001 | B2: 环氧酚醛 | C2: 205 | D2: 17 | F2: 镀铬铁 | G2: 8.6 | H2: 14#
A3: EP-0002 | B3: 环氧酚醛 | C3: 205 | D3: 17 | F3: 镀铬铁 | G3: 8.6 | H3: 14#
A4: EP-0003 | B4: 环氧酚醛 | C4: 205 | D4: 17 | F4: 镀铬铁 | G4: 8.6 | H4: 14#
A5: EP-0004 | B5: 环氧酚醛 | C5: 205 | D5: 17 | F5: 镀铬铁 | G5: 8.6 | H5: 14#
A6: EP-0005 | B6: 环氧酚醛 | C6: 205 | D6: 17 | F6: 镀铬铁 | G6: 8.6 | H6: 14#
A7: ORG-0001 | B7: 有机 | C7: 205 | D7: 12 | F7: 镀铬铁 | G7: 25.8.28 | I7: 双涂双烘190+205
A8: ORG-0002 | B8: 有机 | C8: 205 | D8: 12 | F8: 镀铬铁 | G8: 25.9.16
A9: ORG-0003 | B9: 有机 | C9: 205 | D9: 12 | F9: 镀铬铁 | G9: 25.9.18
A10: PES-0001 | B10: 聚酯 | F10: 镀铬铁 | G10: 25.8.20
A11: PES-0002 | B11: 聚酯 | F11: 镀铬铁 | G11: 25.8.28
A12: PES-0003 | B12: 聚酯 | F12: 镀铬铁 | G12: 25.9.18

Sheet 配方级描述符
A1: 样本ID | B1: 系列 | C1: 体系 | D1: 总用量(g) | E1: 组分数量 | F1: 树脂占比 | G1: 固化剂占比 | H1: 溶剂占比 | I1: 助剂占比 | J1: 颜料占比 | K1: 固化剂/树脂比 | L1: 环氧树脂占比 | M1: 酚醛树脂占比 | N1: 聚酯树脂占比 | O1: 乙烯基树脂占比 | P1: 丙烯酸树脂占比 | Q1: 聚氨酯树脂占比 | R1: 加权固含(%) | S1: 加权密度 | T1: 加权分子量 | U1: 加权EEW | V1: 加权酸值 | W1: 加权羟值 | X1: 加权胺值 | Y1: 加权Tg | Z1: 加权沸点 | AA1: 加权闪点 | AB1: 加权δD | AC1: 加权δP | AD1: 加权δH | AE1: 加权极性 | AF1: 加权挥发速率 | AG1: 加权C(%) | AH1: 加权H(%) | AI1: 加权O(%) | AJ1: 加权N(%) | AK1: 加权S(%) | AL1: 加权Cl(%) | AM1: 环氧基密度(mol/100g) | AN1: 羟基密度 | AO1: 羧基密度 | AP1: 酯基密度 | AQ1: 胺基密度 | AR1: 酰胺密度 | AS1: 芳香环密度 | AT1: 醚键密度 | AU1: 蜡含量(%) | AV1: 颜料含量(%)
A2: EP-0001 | B2: EP-A | C2: 环氧酚醛 | D2: =SUMIF('配方明细'!$A$2:$A$93,$A2,'配方明细'!$E$2:$E$93) | E2: =COUNTIF('配方明细'!$A$2:$A$93,$A2) | F2: =IFERROR(SUMIFS('配方明细'!$E$2:$E$93,'配方明细'!$A$2:$A$93,$A2,'配方明细'!$F$2:$F$93,"树脂")/$C2,0) | G2: =IFERROR(SUMIFS('配方明细'!$E$2:$E$93,'配方明细'!$A$2:$A$93,$A2,'配方明细'!$F$2:$F$93,"固化剂")/$C2,0) | H2: =IFERROR(SUMIFS('配方明细'!$E$2:$E$93,'配方明细'!$A$2:$A$93,$A2,'配方明细'!$F$2:$F$93,"溶剂")/$C2,0) | I2: =IFERROR(SUMIFS('配方明细'!$E$2:$E$93,'配方明细'!$A$2:$A$93,$A2,'配方明细'!$F$2:$F$93,"助剂")/$C2,0) | J2: =IFERROR(SUMIFS('配方明细'!$E$2:$E$93,'配方明细'!$A$2:$A$93,$A2,'配方明细'!$F$2:$F$93,"颜料")/$C2,0) | K2: =IF($F2>0,$G2/$F2,0) | L2: =IFERROR(SUMIFS('配方明细'!$E$2:$E$93,'配方明细'!$A$2:$A$93,$A2,'配方明细'!$G$2:$G$93,"环氧")/$C2,0) | M2: =IFERROR(SUMIFS('配方明细'!$E$2:$E$93,'配方明细'!$A$2:$A$93,$A2,'配方明细'!$G$2:$G$93,"酚醛")/$C2,0) | N2: =IFERROR(SUMIFS('配方明细'!$E$2:$E$93,'配方明细'!$A$2:$A$93,$A2,'配方明细'!$G$2:$G$93,"聚酯")/$C2,0) | O2: =IFERROR(SUMIFS('配方明细'!$E$2:$E$93,'配方明细'!$A$2:$A$93,$A2,'配方明细'!$G$2:$G$93,"乙烯基")/$C2,0) | P2: =IFERROR(SUMIFS('配方明细'!$E$2:$E$93,'配方明细'!$A$2:$A$93,$A2,'配方明细'!$G$2:$G$93,"丙烯酸")/$C2,0) | Q2: =IFERROR(SUMIFS('配方明细'!$E$2:$E$93,'配方明细'!$A$2:$A$93,$A2,'配方明细'!$G$2:$G$93,"聚氨酯")/$C2,0) | R2: =IFERROR(SUMPRODUCT(('配方明细'!$A$2:$A$93=$A2)*'配方明细'!$H$2:$H$93)/$C2,0) | S2: =IFERROR(SUMPRODUCT(('配方明细'!$A$2:$A$93=$A2)*'配方明细'!$I$2:$I$93)/$C2,0) | T2: =IFERROR(SUMPRODUCT(('配方明细'!$A$2:$A$93=$A2)*'配方明细'!$J$2:$J$93)/$C2,0) | U2: =IFERROR(SUMPRODUCT(('配方明细'!$A$2:$A$93=$A2)*'配方明细'!$K$2:$K$93)/$C2,0) | V2: =IFERROR(SUMPRODUCT(('配方明细'!$A$2:$A$93=$A2)*'配方明细'!$L$2:$L$93)/$C2,0) | W2: =IFERROR(SUMPRODUCT(('配方明细'!$A$2:$A$93=$A2)*'配方明细'!$M$2:$M$93)/$C2,0) | X2: =IFERROR(SUMPRODUCT(('配方明细'!$A$2:$A$93=$A2)*'配方明细'!$N$2:$N$93)/$C2,0) | Y2: =IFERROR(SUMPRODUCT(('配方明细'!$A$2:$A$93=$A2)*'配方明细'!$O$2:$O$93)/$C2,0) | Z2: =IFERROR(SUMPRODUCT(('配方明细'!$A$2:$A$93=$A2)*'配方明细'!$P$2:$P$93)/$C2,0) | AA2: =IFERROR(SUMPRODUCT(('配方明细'!$A$2:$A$93=$A2)*'配方明细'!$Q$2:$Q$93)/$C2,0) | AB2: =IFERROR(SUMPRODUCT(('配方明细'!$A$2:$A$93=$A2)*'配方明细'!$R$2:$R$93)/$C2,0) | AC2: =IFERROR(SUMPRODUCT(('配方明细'!$A$2:$A$93=$A2)*'配方明细'!$S$2:$S$93)/$C2,0) | AD2: =IFERROR(SUMPRODUCT(('配方明细'!$A$2:$A$93=$A2)*'配方明细'!$T$2:$T$93)/$C2,0) | AE2: =IFERROR(SUMPRODUCT(('配方明细'!$A$2:$A$93=$A2)*'配方明细'!$U$2:$U$93)/$C2,0) | AF2: =IFERROR(SUMPRODUCT(('配方明细'!$A$2:$A$93=$A2)*'配方明细'!$V$2:$V$93)/$C2,0) | AG2: =IFERROR(SUMPRODUCT(('配方明细'!$A$2:$A$93=$A2)*'配方明细'!$W$2:$W$93)/$C2,0) | AH2: =IFERROR(SUMPRODUCT(('配方明细'!$A$2:$A$93=$A2)*'配方明细'!$X$2:$X$93)/$C2,0) | AI2: =IFERROR(SUMPRODUCT(('配方明细'!$A$2:$A$93=$A2)*'配方明细'!$Y$2:$Y$93)/$C2,0) | AJ2: =IFERROR(SUMPRODUCT(('配方明细'!$A$2:$A$93=$A2)*'配方明细'!$Z$2:$Z$93)/$C2,0) | AK2: =IFERROR(SUMPRODUCT(('配方明细'!$A$2:$A$93=$A2)*'配方明细'!$AA$2:$AA$93)/$C2,0) | AL2: =IFERROR(SUMPRODUCT(('配方明细'!$A$2:$A$93=$A2)*'配方明细'!$AB$2:$AB$93)/$C2,0) | AM2: =IFERROR(SUMPRODUCT(('配方明细'!$A$2:$A$93=$A2)*'配方明细'!$AC$2:$AC$93)/$C2,0) | AN2: =IFERROR(SUMPRODUCT(('配方明细'!$A$2:$A$93=$A2)*'配方明细'!$AD$2:$AD$93)/100,0) | AO2: =IFERROR(SUMPRODUCT(('配方明细'!$A$2:$A$93=$A2)*'配方明细'!$AE$2:$AE$93)/100,0) | AP2: =IFERROR(SUMPRODUCT(('配方明细'!$A$2:$A$93=$A2)*'配方明细'!$AF$2:$AF$93)/100,0) | AQ2: =IFERROR(SUMPRODUCT(('配方明细'!$A$2:$A$93=$A2)*'配方明细'!$AG$2:$AG$93)/100,0) | AR2: =IFERROR(SUMPRODUCT(('配方明细'!$A$2:$A$93=$A2)*'配方明细'!$AH$2:$AH$93)/100,0) | AS2: =IFERROR(SUMPRODUCT(('配方明细'!$A$2:$A$93=$A2)*'配方明细'!$AI$2:$AI$93)/100,0) | AT2: =IFERROR(SUMPRODUCT(('配方明细'!$A$2:$A$93=$A2)*'配方明细'!$AJ$2:$AJ$93)/100,0) | AU2: =IFERROR(SUMPRODUCT(('配方明细'!$A$2:$A$93=$A2)*'配方明细'!$AK$2:$AK$93)/100,0) | AV2: =IFERROR(SUMPRODUCT(('配方明细'!$A$2:$A$93=$A2)*'配方明细'!$AL$2:$AL$93)/$C2,0) | AW2: =IFERROR(SUMPRODUCT(('配方明细'!$A$2:$A$93=$A2)*'配方明细'!$AM$2:$AM$93)/$C2,0)
A3: EP-0002 | B3: EP-A | C3: 环氧酚醛 | D3: =SUMIF('配方明细'!$A$2:$A$93,$A3,'配方明细'!$E$2:$E$93) | E3: =COUNTIF('配方明细'!$A$2:$A$93,$A3) | F3: =IFERROR(SUMIFS('配方明细'!$E$2:$E$93,'配方明细'!$A$2:$A$93,$A3,'配方明细'!$F$2:$F$93,"树脂")/$C3,0) | G3: =IFERROR(SUMIFS('配方明细'!$E$2:$E$93,'配方明细'!$A$2:$A$93,$A3,'配方明细'!$F$2:$F$93,"固化剂")/$C3,0) | H3: =IFERROR(SUMIFS('配方明细'!$E$2:$E$93,'配方明细'!$A$2:$A$93,$A3,'配方明细'!$F$2:$F$93,"溶剂")/$C3,0) | I3: =IFERROR(SUMIFS('配方明细'!$E$2:$E$93,'配方明细'!$A$2:$A$93,$A3,'配方明细'!$F$2:$F$93,"助剂")/$C3,0) | J3: =IFERROR(SUMIFS('配方明细'!$E$2:$E$93,'配方明细'!$A$2:$A$93,$A3,'配方明细'!$F$2:$F$93,"颜料")/$C3,0) | K3: =IF($F3>0,$G3/$F3,0) | L3: =IFERROR(SUMIFS('配方明细'!$E$2:$E$93,'配方明细'!$A$2:$A$93,$A3,'配方明细'!$G$2:$G$93,"环氧")/$C3,0) | M3: =IFERROR(SUMIFS('配方明细'!$E$2:$E$93,'配方明细'!$A$2:$A$93,$A3,'配方明细'!$G$2:$G$93,"酚醛")/$C3,0) | N3: =IFERROR(SUMIFS('配方明细'!$E$2:$E$93,'配方明细'!$A$2:$A$93,$A3,'配方明细'!$G$2:$G$93,"聚酯")/$C3,0) | O3: =IFERROR(SUMIFS('配方明细'!$E$2:$E$93,'配方明细'!$A$2:$A$93,$A3,'配方明细'!$G$2:$G$93,"乙烯基")/$C3,0) | P3: =IFERROR(SUMIFS('配方明细'!$E$2:$E$93,'配方明细'!$A$2:$A$93,$A3,'配方明细'!$G$2:$G$93,"丙烯酸")/$C3,0) | Q3: =IFERROR(SUMIFS('配方明细'!$E$2:$E$93,'配方明细'!$A$2:$A$93,$A3,'配方明细'!$G$2:$G$93,"聚氨酯")/$C3,0) | R3: =IFERROR(SUMPRODUCT(('配方明细'!$A$2:$A$93=$A3)*'配方明细'!$H$2:$H$93)/$C3,0) | S3: =IFERROR(SUMPRODUCT(('配方明细'!$A$2:$A$93=$A3)*'配方明细'!$I$2:$I$93)/$C3,0) | T3: =IFERROR(SUMPRODUCT(('配方明细'!$A$2:$A$93=$A3)*'配方明细'!$J$2:$J$93)/$C3,0) | U3: =IFERROR(SUMPRODUCT(('配方明细'!$A$2:$A$93=$A3)*'配方明细'!$K$2:$K$93)/$C3,0) | V3: =IFERROR(SUMPRODUCT(('配方明细'!$A$2:$A$93=$A3)*'配方明细'!$L$2:$L$93)/$C3,0) | W3: =IFERROR(SUMPRODUCT(('配方明细'!$A$2:$A$93=$A3)*'配方明细'!$M$2:$M$93)/$C3,0) | X3: =IFERROR(SUMPRODUCT(('配方明细'!$A$2:$A$93=$A3)*'配方明细'!$N$2:$N$93)/$C3,0) | Y3: =IFERROR(SUMPRODUCT(('配方明细'!$A$2:$A$93=$A3)*'配方明细'!$O$2:$O$93)/$C3,0) | Z3: =IFERROR(SUMPRODUCT(('配方明细'!$A$2:$A$93=$A3)*'配方明细'!$P$2:$P$93)/$C3,0) | AA3: =IFERROR(SUMPRODUCT(('配方明细'!$A$2:$A$93=$A3)*'配方明细'!$Q$2:$Q$93)/$C3,0) | AB3: =IFERROR(SUMPRODUCT(('配方明细'!$A$2:$A$93=$A3)*'配方明细'!$R$2:$R$93)/$C3,0) | AC3: =IFERROR(SUMPRODUCT(('配方明细'!$A$2:$A$93=$A3)*'配方明细'!$S$2:$S$93)/$C3,0) | AD3: =IFERROR(SUMPRODUCT(('配方明细'!$A$2:$A$93=$A3)*'配方明细'!$T$2:$T$93)/$C3,0) | AE3: =IFERROR(SUMPRODUCT(('配方明细'!$A$2:$A$93=$A3)*'配方明细'!$U$2:$U$93)/$C3,0) | AF3: =IFERROR(SUMPRODUCT(('配方明细'!$A$2:$A$93=$A3)*'配方明细'!$V$2:$V$93)/$C3,0) | AG3: =IFERROR(SUMPRODUCT(('配方明细'!$A$2:$A$93=$A3)*'配方明细'!$W$2:$W$93)/$C3,0) | AH3: =IFERROR(SUMPRODUCT(('配方明细'!$A$2:$A$93=$A3)*'配方明细'!$X$2:$X$93)/$C3,0) | AI3: =IFERROR(SUMPRODUCT(('配方明细'!$A$2:$A$93=$A3)*'配方明细'!$Y$2:$Y$93)/$C3,0) | AJ3: =IFERROR(SUMPRODUCT(('配方明细'!$A$2:$A$93=$A3)*'配方明细'!$Z$2:$Z$93)/$C3,0) | AK3: =IFERROR(SUMPRODUCT(('配方明细'!$A$2:$A$93=$A3)*'配方明细'!$AA$2:$AA$93)/$C3,0) | AL3: =IFERROR(SUMPRODUCT(('配方明细'!$A$2:$A$93=$A3)*'配方明细'!$AB$2:$AB$93)/$C3,0) | AM3: =IFERROR(SUMPRODUCT(('配方明细'!$A$2:$A$93=$A3)*'配方明细'!$AC$2:$AC$93)/$C3,0) | AN3: =IFERROR(SUMPRODUCT(('配方明细'!$A$2:$A$93=$A3)*'配方明细'!$AD$2:$AD$93)/100,0) | AO3: =IFERROR(SUMPRODUCT(('配方明细'!$A$2:$A$93=$A3)*'配方明细'!$AE$2:$AE$93)/100,0) | AP3: =IFERROR(SUMPRODUCT(('配方明细'!$A$2:$A$93=$A3)*'配方明细'!$AF$2:$AF$93)/100,0) | AQ3: =IFERROR(SUMPRODUCT(('配方明细'!$A$2:$A$93=$A3)*'配方明细'!$AG$2:$AG$93)/100,0) | AR3: =IFERROR(SUMPRODUCT(('配方明细'!$A$2:$A$93=$A3)*'配方明细'!$AH$2:$AH$93)/100,0) | AS3: =IFERROR(SUMPRODUCT(('配方明细'!$A$2:$A$93=$A3)*'配方明细'!$AI$2:$AI$93)/100,0) | AT3: =IFERROR(SUMPRODUCT(('配方明细'!$A$2:$A$93=$A3)*'配方明细'!$AJ$2:$AJ$93)/100,0) | AU3: =IFERROR(SUMPRODUCT(('配方明细'!$A$2:$A$93=$A3)*'配方明细'!$AK$2:$AK$93)/100,0) | AV3: =IFERROR(SUMPRODUCT(('配方明细'!$A$2:$A$93=$A3)*'配方明细'!$AL$2:$AL$93)/$C3,0) | AW3: =IFERROR(SUMPRODUCT(('配方明细'!$A$2:$A$93=$A3)*'配方明细'!$AM$2:$AM$93)/$C3,0)
